Workbook
Name RoomList: [1]!RoomLookup[#Data]

Sheet MAY 2024 - Working File 
A1: Sl | B1: ID | C1: Names | D1: Mol Person ID | E1: Cont salry | F1: Basic | G1: days | H1: Abs. | I1: pres | J1: Basic Salary | K1: Wps OT Hours | L1: WPS OT Salary | M1: NON wps OT Hours | N1: NON wps OT Salary | O1: Sunday OT Hours | P1: Sunday OT Amount | Q1: food days | R1: Food Allow | S1: Food Amount | T1: Full att. | U1: Incen. | V1: Add. | W1: Dedu. | X1: Total salary | Y1: Addition Reason | Z1: Deduction Reason | AA1: WPS basic | AB1: NON WPS - | AC1: Total Sent | AD1: Balance | AE1: WPS Provided | AF1: Non WPS to be sent
A2: 1 | B2: 75 | C2: MD SHAHBAZ MUHAMMAD AFZAL | D2: 20019038501917 | F2: 800 | G2: 31 | H2: 0 | I2: =G2-H2 -> 31 | J2: =F2/G2*I2 -> 800 | L2: =F2/30/8*1.25*K2 -> 0 | N2: =F2/30/8*1.25*M2 -> 0 | P2: =F2/30/8*1.5*O2 -> 0 | Q2: =I2 -> 31 | R2: 200 | S2: =R2/G2*Q2 -> 200 | T2: =100/G2*I2 -> 100 | U2: 100 | V2: 0 | W2: 0 | X2: =J2+L2+N2+P2+S2+T2+U2+V2-W2 -> 1200 | AA2: =J2 -> 800 | AB2: =X2-AA2 -> 400 | AC2: =AE2+AB2 -> #N/A | AD2: =X2-AC2 -> #N/A | AE2: =VLOOKUP(B2,[2]Sheet1!$B$4:$J$188,9,0) -> #N/A | AF2: =X2-AE2 -> #N/A | AG2: =VLOOKUP(B2,'[3]MASTER -COLOR CODE'!$B$6:$C$337,2,0) -> MUHAMMAD SHAHBAZ
A3: 2 | B3: 88 | C3: AMIR SHAHZAD GHULAM RASOOL | D3: 20014098680204 | F3: 800 | G3: 31 | H3: 0 | I3: =G3-H3 -> 31 | J3: =F3/G3*I3 -> 800 | L3: =F3/30/8*1.25*K3 -> 0 | N3: =F3/30/8*1.25*M3 -> 0 | P3: =F3/30/8*1.5*O3 -> 0 | Q3: =I3 -> 31 | R3: 200 | S3: =R3/G3*Q3 -> 200 | T3: =100/G3*I3 -> 100 | U3: 100 | V3: 0 | W3: 0 | X3: =J3+L3+N3+P3+S3+T3+U3+V3-W3 -> 1200 | AA3: =J3 -> 800 | AB3: =X3-AA3 -> 400 | AC3: =AE3+AB3 -> #N/A | AD3: =X3-AC3 -> #N/A | AE3: =VLOOKUP(B3,[2]Sheet1!$B$4:$J$188,9,0) -> #N/A | AF3: =X3-AE3 -> #N/A | AG3: =VLOOKUP(B3,'[3]MASTER -COLOR CODE'!$B$6:$C$337,2,0) -> AMIR SHAHZAD GHULAM RASOOL
A4: 3 | B4: 182 | C4: Horamoni | D4: 30115037730750 | F4: 800 | G4: 31 | H4: 0 | I4: =G4-H4 -> 31 | J4: =F4/G4*I4 -> 800 | L4: =F4/30/8*1.25*K4 -> 0 | N4: =F4/30/8*1.25*M4 -> 0 | P4: =F4/30/8*1.5*O4 -> 0 | Q4: =I4 -> 31 | R4: 200 | S4: =R4/G4*Q4 -> 200 | T4: 100 | U4: 100 | V4: 0 | W4: 0 | X4: =J4+L4+N4+P4+S4+T4+U4+V4-W4 -> 1200 | AA4: =J4 -> 800 | AB4: =X4-AA4 -> 400 | AC4: =AE4+AB4 -> #N/A | AD4: =X4-AC4 -> #N/A | AE4: =VLOOKUP(B4,[2]Sheet1!$B$4:$J$188,9,0) -> #N/A | AF4: =X4-AE4 -> #N/A | AG4: =VLOOKUP(B4,'[3]MASTER -COLOR CODE'!$B$6:$C$337,2,0) -> HORA MONI MOJMDER ANOWTA KUMARR
A5: 4 | B5: 189 | C5: KAMAL ABDUR RAHMAN | D5: 30101017385850 | F5: 800 | G5: 31 | H5: 0 | I5: =G5-H5 -> 31 | J5: =F5/G5*I5 -> 800 | L5: =F5/30/8*1.25*K5 -> 0 | N5: =F5/30/8*1.25*M5 -> 0 | P5: =F5/30/8*1.5*O5 -> 0 | Q5: =I5 -> 31 | R5: 200 | S5: =R5/G5*Q5 -> 200 | T5: =100/G5*I5 -> 100 | U5: 100 | V5: 0 | W5: 0 | X5: =J5+L5+N5+P5+S5+T5+U5+V5-W5 -> 1200 | AA5: =J5 -> 800 | AB5: =X5-AA5 -> 400 | AC5: =AE5+AB5 -> #N/A | AD5: =X5-AC5 -> #N/A | AE5: =VLOOKUP(B5,[2]Sheet1!$B$4:$J$188,9,0) -> #N/A | AF5: =X5-AE5 -> #N/A | AG5: =VLOOKUP(B5,'[3]MASTER -COLOR CODE'!$B$6:$C$337,2,0) -> KAMAL ABDUL REHMAN
A6: 5 | B6: 213 | C6: MUBARAK KALU BHUIYAN | D6: 30110108452099 | F6: 800 | G6: 31 | H6: 0 | I6: =G6-H6 -> 31 | J6: =F6/G6*I6 -> 800 | L6: =F6/30/8*1.25*K6 -> 0 | N6: =F6/30/8*1.25*M6 -> 0 | P6: =F6/30/8*1.5*O6 -> 0 | Q6: =I6 -> 31 | R6: 200 | S6: =R6/G6*Q6 -> 200 | T6: =100/G6*I6 -> 100 | U6: 100 | V6: 0 | W6: 0 | X6: =J6+L6+N6+P6+S6+T6+U6+V6-W6 -> 1200 | AA6: =J6 -> 800 | AB6: =X6-AA6 -> 400 | AC6: =AE6+AB6 -> #N/A | AD6: =X6-AC6 -> #N/A | AE6: =VLOOKUP(B6,[2]Sheet1!$B$4:$J$188,9,0) -> #N/A | AF6: =X6-AE6 -> #N/A | AG6: =VLOOKUP(B6,'[3]MASTER -COLOR CODE'!$B$6:$C$337,2,0) -> MUBARAK KALU BHUIYAN
A7: 6 | B7: 231 | C7: MORSHAD ALAM ABUL KALAM | D7: 30121098730725 | F7: 800 | G7: 31 | H7: 0 | I7: =G7-H7 -> 31 | J7: =F7/G7*I7 -> 800 | L7: =F7/30/8*1.25*K7 -> 0 | N7: =F7/30/8*1.25*M7 -> 0 | P7: =F7/30/8*1.5*O7 -> 0 | Q7: =I7 -> 31 | R7: 200 | S7: =R7/G7*Q7 -> 200 | T7: =100/G7*I7 -> 100 | U7: 100 | V7: 0 | W7: 0 | X7: =J7+L7+N7+P7+S7+T7+U7+V7-W7 -> 1200 | AA7: =J7 -> 800 | AB7: =X7-AA7 -> 400 | AC7: =AE7+AB7 -> #N/A | AD7: =X7-AC7 -> #N/A | AE7: =VLOOKUP(B7,[2]Sheet1!$B$4:$J$188,9,0) -> #N/A | AF7: =X7-AE7 -> #N/A | AG7: =VLOOKUP(B7,'[3]MASTER -COLOR CODE'!$B$6:$C$337,2,0) -> MORSHAD ALAM ABUL KALAM
A8: 7 | B8: 234 | C8: AZIZAR MD ROSHAN | D8: 30106097574397 | F8: 800 | G8: 31 | H8: 0 | I8: =G8-H8 -> 31 | J8: =F8/G8*I8 -> 800 | L8: =F8/30/8*1.25*K8 -> 0 | N8: =F8/30/8*1.25*M8 -> 0 | P8: =F8/30/8*1.5*O8 -> 0 | Q8: =I8 -> 31 | R8: 200 | S8: =R8/G8*Q8 -> 200 | T8: =100/G8*I8 -> 100 | U8: 100 | V8: 0 | W8: 0 | X8: =J8+L8+N8+P8+S8+T8+U8+V8-W8 -> 1200 | AA8: =J8 -> 800 | AB8: =X8-AA8 -> 400 | AC8: =AE8+AB8 -> #N/A | AD8: =X8-AC8 -> #N/A | AE8: =VLOOKUP(B8,[2]Sheet1!$B$4:$J$188,9,0) -> #N/A | AF8: =X8-AE8 -> #N/A | AG8: =VLOOKUP(B8,'[3]MASTER -COLOR CODE'!$B$6:$C$337,2,0) -> AZIZAR MD. ROSHAN
A9: 8 | B9: 245 | C9: Abu Bakkar | D9: 30115068845431 | F9: 800 | G9: 31 | H9: 0 | I9: =G9-H9 -> 31 | J9: =F9/G9*I9 -> 800 | L9: =F9/30/8*1.25*K9 -> 0 | N9: =F9/30/8*1.25*M9 -> 0 | P9: =F9/30/8*1.5*O9 -> 0 | Q9: =I9 -> 31 | R9: 200 | S9: =R9/G9*Q9 -> 200 | T9: =100/G9*I9 -> 100 | U9: 100 | V9: 0 | W9: 0 | X9: =J9+L9+N9+P9+S9+T9+U9+V9-W9 -> 1200 | AA9: =J9 -> 800 | AB9: =X9-AA9 -> 400 | AC9: =AE9+AB9 -> #N/A | AD9: =X9-AC9 -> #N/A | AE9: =VLOOKUP(B9,[2]Sheet1!$B$4:$J$188,9,0) -> #N/A | AF9: =X9-AE9 -> #N/A | AG9: =VLOOKUP(B9,'[3]MASTER -COLOR CODE'!$B$6:$C$337,2,0) -> ABU BAKKAR LATE ABDUL GONU MIAH
A10: 9 | B10: 247 | C10: NAZRUL ABDUL MALAK | D10: 30111058345445 | F10: 800 | G10: 31 | H10: 0 | I10: =G10-H10 -> 31 | J10: =F10/G10*I10 -> 800 | L10: =F10/30/8*1.25*K10 -> 0 | N10: =F10/30/8*1.25*M10 -> 0 | P10: =F10/30/8*1.5*O10 -> 0 | Q10: =I10 -> 31 | R10: 200 | S10: =R10/G10*Q10 -> 200 | T10: =100/G10*I10 -> 100 | U10: 100 | V10: 0 | W10: 0 | X10: =J10+L10+N10+P10+S10+T10+U10+V10-W10 -> 1200 | AA10: =J10 -> 800 | AB10: =X10-AA10 -> 400 | AC10: =AE10+AB10 -> #N/A | AD10: =X10-AC10 -> #N/A | AE10: =VLOOKUP(B10,[2]Sheet1!$B$4:$J$188,9,0) -> #N/A | AF10: =X10-AE10 -> #N/A | AG10: =VLOOKUP(B10,'[3]MASTER -COLOR CODE'!$B$6:$C$337,2,0) -> NAZRUL ABDUL MALAK
A11: 10 | B11: 250 | C11: JAKIR HOSSAIN SIRAJ UDDOULA | D11: 30121088324437 | F11: 800 | G11: 31 | H11: 0 | I11: =G11-H11 -> 31 | J11: =F11/G11*I11 -> 800 | L11: =F11/30/8*1.25*K11 -> 0 | N11: =F11/30/8*1.25*M11 -> 0 | P11: =F11/30/8*1.5*O11 -> 0 | Q11: =I11 -> 31 | R11: 200 | S11: =R11/G11*Q11 -> 200 | T11: =100/G11*I11 -> 100 | U11: 100 | V11: 0 | W11: 0 | X11: =J11+L11+N11+P11+S11+T11+U11+V11-W11 -> 1200 | AA11: =J11 -> 800 | AB11: =X11-AA11 -> 400 | AC11: =AE11+AB11 -> #N/A | AD11: =X11-AC11 -> #N/A | AE11: =VLOOKUP(B11,[2]Sheet1!$B$4:$J$188,9,0) -> #N/A | AF11: =X11-AE11 -> #N/A | AG11: =VLOOKUP(B11,'[3]MASTER -COLOR CODE'!$B$6:$C$337,2,0) -> JAKIR HOSSAIN SIRAJ UDDOULA
A12: 11 | B12: 265 | C12: Jamal Abdul Rahman | D12: 30115037745449 | F12: 800 | G12: 31 | H12: 0 | I12: =G12-H12 -> 31 | J12: =F12/G12*I12 -> 800 | L12: =F12/30/8*1.25*K12 -> 0 | N12: =F12/30/8*1.25*M12 -> 0 | P12: =F12/30/8*1.5*O12 -> 0 | Q12: =I12 -> 31 | R12: 200 | S12: =R12/G12*Q12 -> 200 | T12: =100/G12*I12 -> 100 | U12: 200 | V12: 0 | W12: 0 | X12: =J12+L12+N12+P12+S12+T12+U12+V12-W12 -> 1300 | AA12: =J12 -> 800 | AB12: =X12-AA12 -> 500 | AC12: =AE12+AB12 -> #N/A | AD12: =X12-AC12 -> #N/A | AE12: =VLOOKUP(B12,[2]Sheet1!$B$4:$J$188,9,0) -> #N/A | AF12: =X12-AE12 -> #N/A | AG12: =VLOOKUP(B12,'[3]MASTER -COLOR CODE'!$B$6:$C$337,2,0) -> JAMAL ABDUL RAHMAN
A13: 12 | B13: 412 | C13: DEBU BAIRAGI BAIRAGI DHIREN | D13: 10003037114062 | F13: 800 | G13: 31 | H13: 2 | I13: =G13-H13 -> 29 | J13: =F13/G13*I13 -> 748.3871 | L13: =F13/30/8*1.25*K13 -> 0 | N13: =F13/30/8*1.25*M13 -> 0 | P13: =F13/30/8*1.5*O13 -> 0 | Q13: =I13 -> 29 | R13: 200 | S13: =R13/G13*Q13 -> 187.09677 | T13: =100/G13*I13 -> 93.548387 | U13: 200 | V13: 0 | W13: 0 | X13: =J13+L13+N13+P13+S13+T13+U13+V13-W13 -> 1229.0323 | AA13: =J13 -> 748.3871 | AB13: =X13-AA13 -> 480.64516 | AC13: =AE13+AB13 -> #N/A | AD13: =X13-AC13 -> #N/A | AE13: =VLOOKUP(B13,[2]Sheet1!$B$4:$J$188,9,0) -> #N/A | AF13: =X13-AE13 -> #N/A | AG13: =VLOOKUP(B13,'[3]MASTER -COLOR CODE'!$B$6:$C$337,2,0) -> DEBU BAIRAGI BAIRAGI DHIREN
A14: 13 | B14: 469 | C14: LALAN PRASAD INDRASAN PRASAD | D14: 10004028926930 | F14: 800 | G14: 31 | H14: 3 | I14: =G14-H14 -> 28 | J14: =F14/G14*I14 -> 722.58065 | L14: =F14/30/8*1.25*K14 -> 0 | N14: =F14/30/8*1.25*M14 -> 0 | P14: =F14/30/8*1.5*O14 -> 0 | Q14: =I14 -> 28 | R14: 200 | S14: =R14/G14*Q14 -> 180.64516 | T14: 100 | U14: 200 | V14: 0 | W14: 0 | X14: =J14+L14+N14+P14+S14+T14+U14+V14-W14 -> 1203.2258 | AA14: =J14 -> 722.58065 | AB14: =X14-AA14 -> 480.64516 | AC14: =AE14+AB14 -> #N/A | AD14: =X14-AC14 -> #N/A | AE14: =VLOOKUP(B14,[2]Sheet1!$B$4:$J$188,9,0) -> #N/A | AF14: =X14-AE14 -> #N/A | AG14: =VLOOKUP(B14,'[3]MASTER -COLOR CODE'!$B$6:$C$337,2,0) -> LALAN PARSAD
A15: 14 | B15: 505 | C15: LAKSHMAN BISWAS ANANDA | D15: 10002048850784 | F15: 800 | G15: 31 | H15: 0 | I15: =G15-H15 -> 31 | J15: =F15/G15*I15 -> 800 | L15: =F15/30/8*1.25*K15 -> 0 | N15: =F15/30/8*1.25*M15 -> 0 | P15: =F15/30/8*1.5*O15 -> 0 | Q15: =I15 -> 31 | R15: 200 | S15: =R15/G15*Q15 -> 200 | T15: =100/G15*I15 -> 100 | U15: 200 | V15: 0 | W15: 0 | X15: =J15+L15+N15+P15+S15+T15+U15+V15-W15 -> 1300 | AA15: =J15 -> 800 | AB15: =X15-AA15 -> 500 | AC15: =AE15+AB15 -> #N/A | AD15: =X15-AC15 -> #N/A | AE15: =VLOOKUP(B15,[2]Sheet1!$B$4:$J$188,9,0) -> #N/A | AF15: =X15-AE15 -> #N/A | AG15: =VLOOKUP(B15,'[3]MASTER -COLOR CODE'!$B$6:$C$337,2,0) -> LAKSHMAN BISWAS ANANDA
A16: 15 | B16: 583 | C16: Inayat Ullah | D16: 20006118663043 | F16: 700 | G16: 31 | H16: 0 | I16: =G16-H16 -> 31 | J16: =F16/G16*I16 -> 700 | L16: =F16/30/8*1.25*K16 -> 0 | N16: =F16/30/8*1.25*M16 -> 0 | P16: =F16/30/8*1.5*O16 -> 0 | Q16: =I16 -> 31 | R16: 200 | S16: =R16/G16*Q16 -> 200 | T16: =100/G16*I16 -> 100 | U16: 100 | V16: 0 | W16: 0 | X16: =J16+L16+N16+P16+S16+T16+U16+V16-W16 -> 1100 | AA16: =J16 -> 700 | AB16: =X16-AA16 -> 400 | AC16: =AE16+AB16 -> #N/A | AD16: =X16-AC16 -> #N/A | AE16: =VLOOKUP(B16,[2]Sheet1!$B$4:$J$188,9,0) -> #N/A | AF16: =X16-AE16 -> #N/A | AG16: =VLOOKUP(B16,'[3]MASTER -COLOR CODE'!$B$6:$C$337,2,0) -> INAYAT ULLAH SAHIB ZADA
A17: 16 | B17: 603 | C17: TAUSEEF ALI BAGHDAD SHAH | D17: 20001019222955 | F17: 700 | G17: 31 | H17: 0 | I17: =G17-H17 -> 31 | J17: =F17/G17*I17 -> 700 | L17: =F17/30/8*1.25*K17 -> 0 | N17: =F17/30/8*1.25*M17 -> 0 | P17: =F17/30/8*1.5*O17 -> 0 | Q17: =I17 -> 31 | R17: 200 | S17: =R17/G17*Q17 -> 200 | T17: 100 | U17: 100 | V17: 0 | W17: 0 | X17: =J17+L17+N17+P17+S17+T17+U17+V17-W17 -> 1100 | AA17: =J17 -> 700 | AB17: =X17-AA17 -> 400 | AC17: =AE17+AB17 -> #N/A | AD17: =X17-AC17 -> #N/A | AE17: =VLOOKUP(B17,[2]Sheet1!$B$4:$J$188,9,0) -> #N/A | AF17: =X17-AE17 -> #N/A | AG17: =VLOOKUP(B17,'[3]MASTER -COLOR CODE'!$B$6:$C$337,2,0) -> TOUSEEF ALI
A18: 17 | B18: 604 | C18: Imdad Ali | F18: 700 | G18: 31 | H18: 0 | I18: =G18-H18 -> 31 | J18: =F18/G18*I18 -> 700 | L18: =F18/30/8*1.25*K18 -> 0 | N18: =F18/30/8*1.25*M18 -> 0 | P18: =F18/30/8*1.5*O18 -> 0 | Q18: =I18 -> 31 | R18: 200 | S18: =R18/G18*Q18 -> 200 | T18: 100 | U18: 200 | V18: 0 | W18: 0 | X18: =J18+L18+N18+P18+S18+T18+U18+V18-W18 -> 1200 | AA18: =J18 -> 700 | AB18: =X18-AA18 -> 500 | AC18: =AE18+AB18 -> #N/A | AD18: =X18-AC18 -> #N/A | AE18: =VLOOKUP(B18,[2]Sheet1!$B$4:$J$188,9,0) -> #N/A | AF18: =X18-AE18 -> #N/A | AG18: =VLOOKUP(B18,'[3]MASTER -COLOR CODE'!$B$6:$C$337,2,0) -> IMDAD ALI BHUTO
A19: 18 | B19: 606 | C19: AZEEM KHAN | D19: 30110108452099 | F19: 900 | G19: 31 | H19: 31 | I19: =G19-H19 -> 0 | J19: =F19/G19*I19 -> 0 | L19: =F19/30/8*1.25*K19 -> 0 | N19: =F19/30/8*1.25*M19 -> 0 | P19: =F19/30/8*1.5*O19 -> 0 | Q19: =I19 -> 0 | R19: 200 | S19: 200 | T19: 100 | U19: 200 | V19: 0 | W19: 0 | X19: =J19+L19+N19+P19+S19+T19+U19+V19-W19 -> 500 | AA19: =J19 -> 0 | AB19: =X19-AA19 -> 500 | AC19: =AE19+AB19 -> #N/A | AD19: =X19-AC19 -> #N/A | AE19: =VLOOKUP(B19,[2]Sheet1!$B$4:$J$188,9,0) -> #N/A | AF19: =X19-AE19 -> #N/A | AG19: =VLOOKUP(B19,'[3]MASTER -COLOR CODE'!$B$6:$C$337,2,0) -> AZEEM KHAN
A20: 19 | B20: 626 | C20: RIYAJUDDEEN ANSARI RAHAMAN ANSARI | D20: 10025038772389 | F20: 900 | G20: 31 | H20: 0 | I20: =G20-H20 -> 31 | J20: =F20/G20*I20 -> 900 | L20: =F20/30/8*1.25*K20 -> 0 | N20: =F20/30/8*1.25*M20 -> 0 | P20: =F20/30/8*1.5*O20 -> 0 | Q20: =I20 -> 31 | R20: 200 | S20: =R20/G20*Q20 -> 200 | T20: 100 | U20: 0 | V20: 0 | W20: 0 | X20: =J20+L20+N20+P20+S20+T20+U20+V20-W20 -> 1200 | AA20: =J20 -> 900 | AB20: =X20-AA20 -> 300 | AC20: =AE20+AB20 -> #N/A | AD20: =X20-AC20 -> #N/A | AE20: =VLOOKUP(B20,[2]Sheet1!$B$4:$J$188,9,0) -> #N/A | AF20: =X20-AE20 -> #N/A | AG20: =VLOOKUP(B20,'[3]MASTER -COLOR CODE'!$B$6:$C$337,2,0) -> RIYAJUDDEEN ANSARI
A21: 20 | B21: 628 | C21: DIPAK RAM BABAN RAM | D21: 10005108839927 | F21: 900 | G21: 31 | H21: 0 | I21: =G21-H21 -> 31 | J21: =F21/G21*I21 -> 900 | L21: =F21/30/8*1.25*K21 -> 0 | N21: =F21/30/8*1.25*M21 -> 0 | P21: =F21/30/8*1.5*O21 -> 0 | Q21: =I21 -> 31 | R21: 200 | S21: =R21/G21*Q21 -> 200 | T21: 0 | U21: 0 | V21: 0 | W21: 0 | X21: =J21+L21+N21+P21+S21+T21+U21+V21-W21 -> 1100 | AA21: =J21 -> 900 | AB21: =X21-AA21 -> 200 | AC21: =AE21+AB21 -> #N/A | AD21: =X21-AC21 -> #N/A | AE21: =VLOOKUP(B21,[2]Sheet1!$B$4:$J$188,9,0) -> #N/A | AF21: =X21-AE21 -> #N/A | AG21: =VLOOKUP(B21,'[3]MASTER -COLOR CODE'!$B$6:$C$337,2,0) -> DIPAK RAM
A22: 21 | B22: 631 | C22: Arsalan | D22: 20019089539915 | F22: 700 | G22: 31 | H22: 0 | I22: =G22-H22 -> 31 | J22: =F22/G22*I22 -> 700 | L22: =F22/30/8*1.25*K22 -> 0 | N22: =F22/30/8*1.25*M22 -> 0 | P22: =F22/30/8*1.5*O22 -> 0 | Q22: =I22 -> 31 | R22: 200 | S22: =R22/G22*Q22 -> 200 | T22: 0 | U22: 0 | V22: 0 | W22: 0 | X22: =J22+L22+N22+P22+S22+T22+U22+V22-W22 -> 900 | AA22: =J22 -> 700 | AB22: 266 | AC22: =AA22+AB22 -> 966 | AD22: =X22-AC22 -> -66 | AE22: =VLOOKUP(B22,[2]Sheet1!$B$4:$J$188,9,0) -> #N/A | AF22: =X22-AE22 -> #N/A | AG22: =VLOOKUP(B22,'[3]MASTER -COLOR CODE'!$B$6:$C$337,2,0) -> ARSLAN MAHMOOD
A23: 22 | B23: 652 | C23: RAM VILASH SINGH YADAV | D23: 10001017970483 | F23: 900 | G23: 31 | H23: 0 | I23: =G23-H23 -> 31 | J23: =F23/G23*I23 -> 900 | L23: =F23/30/8*1.25*K23 -> 0 | N23: =F23/30/8*1.25*M23 -> 0 | P23: =F23/30/8*1.5*O23 -> 0 | Q23: =I23 -> 31 | R23: 200 | S23: =R23/G23*Q23 -> 200 | T23: 100 | U23: 0 | V23: 0 | W23: 0 | X23: =J23+L23+N23+P23+S23+T23+U23+V23-W23 -> 1200 | AA23: =J23 -> 900 | AB23: =X23-AA23 -> 300 | AC23: =AE23+AB23 -> #N/A | AD23: =X23-AC23 -> #N/A | AE23: =VLOOKUP(B23,[2]Sheet1!$B$4:$J$188,9,0) -> #N/A | AF23: =X23-AE23 -> #N/A | AG23: =VLOOKUP(B23,'[3]MASTER -COLOR CODE'!$B$6:$C$337,2,0) -> RAM VILASH SINGH YADAV
A24: 23 | B24: 654 | C24: RAJNESH SVAMEENATH | D24: 10001128170446 | F24: 900 | G24: 31 | H24: 1 | I24: =G24-H24 -> 30 | J24: =F24/G24*I24 -> 870.96774 | L24: =F24/30/8*1.25*K24 -> 0 | N24: =F24/30/8*1.25*M24 -> 0 | P24: =F24/30/8*1.5*O24 -> 0 | Q24: =I24 -> 30 | R24: 200 | S24: =R24/G24*Q24 -> 193.54839 | T24: 0 | U24: 0 | V24: 0 | W24: 0 | X24: =J24+L24+N24+P24+S24+T24+U24+V24-W24 -> 1064.5161 | AA24: =J24 -> 870.96774 | AB24: =X24-AA24 -> 193.54839 | AC24: =AE24+AB24 -> #N/A | AD24: =X24-AC24 -> #N/A | AE24: =VLOOKUP(B24,[2]Sheet1!$B$4:$J$188,9,0) -> #N/A | AF24: =X24-AE24 -> #N/A | AG24: =VLOOKUP(B24,'[3]MASTER -COLOR CODE'!$B$6:$C$337,2,0) -> RAJNESH SVAMEENADH
A25: 24 | B25: 662 | C25: SHAILESH YADAV VEERA YADAV | D25: 10005029571583 | F25: 900 | G25: 31 | H25: 0 | I25: =G25-H25 -> 31 | J25: =F25/G25*I25 -> 900 | L25: =F25/30/8*1.25*K25 -> 0 | N25: =F25/30/8*1.25*M25 -> 0 | P25: =F25/30/8*1.5*O25 -> 0 | Q25: =I25 -> 31 | R25: 200 | S25: =R25/G25*Q25 -> 200 | T25: =100/G25*I25 -> 100 | U25: 0 | V25: 0 | W25: 0 | X25: =J25+L25+N25+P25+S25+T25+U25+V25-W25 -> 1200 | AA25: =J25 -> 900 | AB25: =X25-AA25 -> 300 | AC25: =AE25+AB25 -> #N/A | AD25: =X25-AC25 -> #N/A | AE25: =VLOOKUP(B25,[2]Sheet1!$B$4:$J$188,9,0) -> #N/A | AF25: =X25-AE25 -> #N/A | AG25: =VLOOKUP(B25,'[3]MASTER -COLOR CODE'!$B$6:$C$337,2,0) -> SHAILESH YADAV
A26: 25 | B26: 669 | C26: Mahendra Thapa | F26: 700 | G26: 31 | H26: 0 | I26: =G26-H26 -> 31 | J26: =F26/G26*I26 -> 700 | L26: =F26/30/8*1.25*K26 -> 0 | N26: =F26/30/8*1.25*M26 -> 0 | P26: =F26/30/8*1.5*O26 -> 0 | Q26: =I26 -> 31 | R26: 200 | S26: =R26/G26*Q26 -> 200 | T26: =100/G26*I26 -> 100 | U26: 0 | V26: 0 | W26: 0 | X26: =J26+L26+N26+P26+S26+T26+U26+V26-W26 -> 1000 | AA26: =J26 -> 700 | AB26: =X26-AA26 -> 300 | AC26: =AE26+AB26 -> #N/A | AD26: =X26-AC26 -> #N/A | AE26: =VLOOKUP(B26,[2]Sheet1!$B$4:$J$188,9,0) -> #N/A | AF26: =X26-AE26 -> #N/A | AG26: =VLOOKUP(B26,'[3]MASTER -COLOR CODE'!$B$6:$C$337,2,0) -> MAHENDRA THAPA
A27: 26 | B27: 670 | C27: BIKRAM YADAV TILAKRAM YADAV | D27: 31621058353025 | F27: 700 | G27: 31 | H27: 0 | I27: =G27-H27 -> 31 | J27: =F27/G27*I27 -> 700 | L27: =F27/30/8*1.25*K27 -> 0 | N27: =F27/30/8*1.25*M27 -> 0 | P27: =F27/30/8*1.5*O27 -> 0 | Q27: =I27 -> 31 | R27: 200 | S27: =R27/G27*Q27 -> 200 | T27: =100/G27*I27 -> 100 | U27: 0 | V27: 0 | W27: 0 | X27: =J27+L27+N27+P27+S27+T27+U27+V27-W27 -> 1000 | AA27: =J27 -> 700 | AB27: =X27-AA27 -> 300 | AC27: =AE27+AB27 -> #N/A | AD27: =X27-AC27 -> #N/A | AE27: =VLOOKUP(B27,[2]Sheet1!$B$4:$J$188,9,0) -> #N/A | AF27: =X27-AE27 -> #N/A | AG27: =VLOOKUP(B27,'[3]MASTER -COLOR CODE'!$B$6:$C$337,2,0) -> BIKRAM YADAV
A28: 27 | B28: 675 | C28: GORAY RAWAL RIULYA RAWAL | D28: 31602018468010 | F28: 700 | G28: 31 | H28: 31 | I28: =G28-H28 -> 0 | J28: =F28/G28*I28 -> 0 | L28: =F28/30/8*1.25*K28 -> 0 | N28: =F28/30/8*1.25*M28 -> 0 | P28: =F28/30/8*1.5*O28 -> 0 | Q28: =I28 -> 0 | R28: 200 | S28: =R28/G28*Q28 -> 0 | T28: =100/G28*I28 -> 0 | U28: 0 | V28: 0 | W28: 0 | X28: =J28+L28+N28+P28+S28+T28+U28+V28-W28 -> 0 | AA28: =J28 -> 0 | AB28: =X28-AA28 -> 0 | AC28: =AE28+AB28 -> #N/A | AD28: =X28-AC28 -> #N/A | AE28: =VLOOKUP(B28,[2]Sheet1!$B$4:$J$188,9,0) -> #N/A | AF28: =X28-AE28 -> #N/A | AG28: =VLOOKUP(B28,'[3]MASTER -COLOR CODE'!$B$6:$C$337,2,0) -> GORAY RAWAL
A29: 28 | B29: 681 | C29: KHALIQ NOOR BADSHAH KHAN | D29: 20019069341390 | F29: 700 | G29: 31 | H29: 1 | I29: =G29-H29 -> 30 | J29: =F29/G29*I29 -> 677.41935 | L29: =F29/30/8*1.25*K29 -> 0 | N29: =F29/30/8*1.25*M29 -> 0 | P29: =F29/30/8*1.5*O29 -> 0 | Q29: =I29 -> 30 | R29: 200 | S29: =R29/G29*Q29 -> 193.54839 | T29: =100/G29*I29 -> 96.774194 | U29: 0 | V29: 0 | W29: 0 | X29: =J29+L29+N29+P29+S29+T29+U29+V29-W29 -> 967.74194 | AA29: =J29 -> 677.41935 | AB29: =X29-AA29 -> 290.32258 | AC29: =AE29+AB29 -> #N/A | AD29: =X29-AC29 -> #N/A | AE29: =VLOOKUP(B29,[2]Sheet1!$B$4:$J$188,9,0) -> #N/A | AF29: =X29-AE29 -> #N/A | AG29: =VLOOKUP(B29,'[3]MASTER -COLOR CODE'!$B$6:$C$337,2,0) -> KHALIQ NOOR BADSHAH
A30: 29 | B30: 693 | C30: AMIT KUMAR UPADHYAY | D30: 10018108203364 | F30: 800 | G30: 31 | H30: 0 | I30: =G30-H30 -> 31 | J30: =F30/G30*I30 -> 800 | L30: =F30/30/8*1.25*K30 -> 0 | N30: =F30/30/8*1.25*M30 -> 0 | P30: =F30/30/8*1.5*O30 -> 0 | Q30: =I30 -> 31 | R30: 200 | S30: =R30/G30*Q30 -> 200 | T30: =100/G30*I30 -> 100 | U30: 0 | V30: 0 | W30: 0 | X30: =J30+L30+N30+P30+S30+T30+U30+V30-W30 -> 1100 | AA30: =J30 -> 800 | AB30: =X30-AA30 -> 300 | AC30: =AE30+AB30 -> #N/A | AD30: =X30-AC30 -> #N/A | AE30: =VLOOKUP(B30,[2]Sheet1!$B$4:$J$188,9,0) -> #N/A | AF30: =X30-AE30 -> #N/A | AG30: =VLOOKUP(B30,'[3]MASTER -COLOR CODE'!$B$6:$C$337,2,0) -> AMIT KUMAR
A31: 30 | B31: 694 | C31: FAJALE ALAM | D31: 10016058097851 | F31: 800 | G31: 31 | H31: 31 | I31: =G31-H31 -> 0 | J31: =F31/G31*I31 -> 0 | L31: =F31/30/8*1.25*K31 -> 0 | N31: =F31/30/8*1.25*M31 -> 0 | P31: =F31/30/8*1.5*O31 -> 0 | Q31: =I31 -> 0 | R31: 200 | S31: =R31/G31*Q31 -> 0 | T31: =100/G31*I31 -> 0 | U31: 0 | V31: 0 | W31: 0 | X31: =J31+L31+N31+P31+S31+T31+U31+V31-W31 -> 0 | AA31: =J31 -> 0 | AB31: =X31-AA31 -> 0 | AC31: =AE31+AB31 -> #N/A | AD31: =X31-AC31 -> #N/A | AE31: =VLOOKUP(B31,[2]Sheet1!$B$4:$J$188,9,0) -> #N/A | AF31: =X31-AE31 -> #N/A | AG31: =VLOOKUP(B31,'[3]MASTER -COLOR CODE'!$B$6:$C$337,2,0) -> FAJALE ALAM FERASAT ALAM
A32: 31 | B32: 695 | C32: TEJ BAHADUR RANA | D32: 31629018468120 | F32: 700 | G32: 31 | H32: 0 | I32: =G32-H32 -> 31 | J32: =F32/G32*I32 -> 700 | L32: =F32/30/8*1.25*K32 -> 0 | N32: =F32/30/8*1.25*M32 -> 0 | P32: =F32/30/8*1.5*O32 -> 0 | Q32: =I32 -> 31 | R32: 200 | S32: =R32/G32*Q32 -> 200 | T32: =100/G32*I32 -> 100 | U32: 0 | V32: 0 | W32: 0 | X32: =J32+L32+N32+P32+S32+T32+U32+V32-W32 -> 1000 | AA32: =J32 -> 700 | AB32: =X32-AA32 -> 300 | AC32: =AE32+AB32 -> #N/A | AD32: =X32-AC32 -> #N/A | AE32: =VLOOKUP(B32,[2]Sheet1!$B$4:$J$188,9,0) -> #N/A | AF32: =X32-AE32 -> #N/A | AG32: =VLOOKUP(B32,'[3]MASTER -COLOR CODE'!$B$6:$C$337,2,0) -> TEJ BAHADUR RANA
A33: 32 | B33: 790 | C33: RABINDRA DAS TATMA | D33: 31624019175423 | F33: 700 | G33: 31 | H33: 0 | I33: =G33-H33 -> 31 | J33: =F33/G33*I33 -> 700 | L33: =F33/30/8*1.25*K33 -> 0 | N33: =F33/30/8*1.25*M33 -> 0 | P33: =F33/30/8*1.5*O33 -> 0 | Q33: =I33 -> 31 | R33: 200 | S33: =R33/G33*Q33 -> 200 | T33: 0 | U33: 100 | V33: 0 | W33: 0 | X33: =J33+L33+N33+P33+S33+T33+U33+V33-W33 -> 1000 | AA33: =J33 -> 700 | AB33: =X33-AA33 -> 300 | AC33: =AE33+AB33 -> #N/A | AD33: =X33-AC33 -> #N/A | AE33: =VLOOKUP(B33,[2]Sheet1!$B$4:$J$188,9,0) -> #N/A | AF33: =X33-AE33 -> #N/A | AG33: =VLOOKUP(B33,'[3]MASTER -COLOR CODE'!$B$6:$C$337,2,0) -> RABINDRA DAS TATMA
A34: 33 | B34: 814 | C34: SANJAY KUMAR MANDAL | D34: 31606019267844 | F34: 700 | G34: 31 | H34: 0 | I34: =G34-H34 -> 31 | J34: =F34/G34*I34 -> 700 | L34: =F34/30/8*1.25*K34 -> 0 | N34: =F34/30/8*1.25*M34 -> 0 | P34: =F34/30/8*1.5*O34 -> 0 | Q34: =I34 -> 31 | R34: 200 | S34: =R34/G34*Q34 -> 200 | T34: =100/G34*I34 -> 100 | U34: 100 | V34: 0 | W34: 0 | X34: =J34+L34+N34+P34+S34+T34+U34+V34-W34 -> 1100 | AA34: =J34 -> 700 | AB34: =X34-AA34 -> 400 | AC34: =AE34+AB34 -> #N/A | AD34: =X34-AC34 -> #N/A | AE34: =VLOOKUP(B34,[2]Sheet1!$B$4:$J$188,9,0) -> #N/A | AF34: =X34-AE34 -> #N/A | AG34: =VLOOKUP(B34,'[3]MASTER -COLOR CODE'!$B$6:$C$337,2,0) -> SANJAY KUMAR MANDAL G
A35: 34 | B35: 818 | C35: Manoj Yadav | D35: 10001018146194 | F35: 900 | G35: 31 | H35: 0 | I35: =G35-H35 -> 31 | J35: =F35/G35*I35 -> 900 | L35: =F35/30/8*1.25*K35 -> 0 | N35: =F35/30/8*1.25*M35 -> 0 | P35: =F35/30/8*1.5*O35 -> 0 | Q35: =I35 -> 31 | R35: 200 | S35: =R35/G35*Q35 -> 200 | T35: 0 | U35: 100 | V35: 0 | W35: 0 | X35: =J35+L35+N35+P35+S35+T35+U35+V35-W35 -> 1200 | AA35: =J35 -> 900 | AB35: =X35-AA35 -> 300 | AC35: =AE35+AB35 -> #N/A | AD35: =X35-AC35 -> #N/A | AE35: =VLOOKUP(B35,[2]Sheet1!$B$4:$J$188,9,0) -> #N/A | AF35: =X35-AE35 -> #N/A | AG35: =VLOOKUP(B35,'[3]MASTER -COLOR CODE'!$B$6:$C$337,2,0) -> MANOJ YADAV
A36: 35 | B36: 821 | C36: Shankar singh | D36: 10013098624851 | F36: 900 | G36: 31 | H36: 0 | I36: =G36-H36 -> 31 | J36: =F36/G36*I36 -> 900 | L36: =F36/30/8*1.25*K36 -> 0 | N36: =F36/30/8*1.25*M36 -> 0 | P36: =F36/30/8*1.5*O36 -> 0 | Q36: =I36 -> 31 | R36: 200 | S36: =R36/G36*Q36 -> 200 | T36: 0 | U36: 100 | V36: 0 | W36: 0 | X36: =J36+L36+N36+P36+S36+T36+U36+V36-W36 -> 1200 | AA36: =J36 -> 900 | AB36: =X36-AE36 -> #N/A | AC36: =AE36+AB36 -> #N/A | AD36: =X36-AC36 -> #N/A | AE36: =VLOOKUP(B36,[2]Sheet1!$B$4:$J$188,9,0) -> #N/A | AF36: =X36-AE36 -> #N/A | AG36: =VLOOKUP(B36,'[3]MASTER -COLOR CODE'!$B$6:$C$337,2,0) -> SHANKAR SINGH
A37: 36 | B37: 836 | C37: Girijesh Paras Nath | D37: 10001018730320 | F37: 700 | G37: 31 | H37: 0 | I37: =G37-H37 -> 31 | J37: =F37/G37*I37 -> 700 | L37: =F37/30/8*1.25*K37 -> 0 | N37: =F37/30/8*1.25*M37 -> 0 | P37: =F37/30/8*1.5*O37 -> 0 | Q37: =I37 -> 31 | R37: 200 | S37: =R37/G37*Q37 -> 200 | T37: =100/G37*I37 -> 100 | U37: 100 | V37: 0 | W37: 0 | X37: =J37+L37+N37+P37+S37+T37+U37+V37-W37 -> 1100 | AA37: =J37 -> 700 | AB37: =X37-AA37 -> 400 | AC37: =AE37+AB37 -> #N/A | AD37: =X37-AC37 -> #N/A | AE37: =VLOOKUP(B37,[2]Sheet1!$B$4:$J$188,9,0) -> #N/A | AF37: =X37-AE37 -> #N/A | AG37: =VLOOKUP(B37,'[3]MASTER -COLOR CODE'!$B$6:$C$337,2,0) -> GIRIJESH GOUTAM
A38: 37 | B38: 837 | C38: Ram lakhan | D38: 10016029156624 | F38: 900 | G38: 31 | H38: 3 | I38: =G38-H38 -> 28 | J38: =F38/G38*I38 -> 812.90323 | L38: =F38/30/8*1.25*K38 -> 0 | N38: =F38/30/8*1.25*M38 -> 0 | P38: =F38/30/8*1.5*O38 -> 0 | Q38: =I38 -> 28 | R38: 200 | S38: =R38/G38*Q38 -> 180.64516 | T38: 0 | U38: 100 | V38: 0 | W38: 0 | X38: =J38+L38+N38+P38+S38+T38+U38+V38-W38 -> 1093.5484 | AA38: =J38 -> 812.90323 | AB38: =X38-AA38 -> 280.64516 | AC38: =AE38+AB38 -> #N/A | AD38: =X38-AC38 -> #N/A | AE38: =VLOOKUP(B38,[2]Sheet1!$B$4:$J$188,9,0) -> #N/A | AF38: =X38-AE38 -> #N/A | AG38: =VLOOKUP(B38,'[3]MASTER -COLOR CODE'!$B$6:$C$337,2,0) -> RAM LAKHAN
A39: 38 | B39: 840 | C39: BAKSHISH JABBAR | F39: 900 | G39: 31 | H39: 0 | I39: =G39-H39 -> 31 | J39: =F39/G39*I39 -> 900 | L39: =F39/30/8*1.25*K39 -> 0 | N39: =F39/30/8*1.25*M39 -> 0 | P39: =F39/30/8*1.5*O39 -> 0 | Q39: =I39 -> 31 | R39: 200 | S39: =R39/G39*Q39 -> 200 | T39: =100/G39*I39 -> 100 | U39: 100 | V39: 0 | W39: 0 | X39: =J39+L39+N39+P39+S39+T39+U39+V39-W39 -> 1300 | AA39: =J39 -> 900 | AB39: =X39-AA39 -> 400 | AC39: =AE39+AB39 -> #N/A | AD39: =X39-AC39 -> #N/A | AE39: =VLOOKUP(B39,[2]Sheet1!$B$4:$J$188,9,0) -> #N/A | AF39: =X39-AE39 -> #N/A | AG39: =VLOOKUP(B39,'[3]MASTER -COLOR CODE'!$B$6:$C$337,2,0) -> BAKSHISH JABBAR
A40: 39 | B40: 848 | C40: DARSHAN AMRIT PAL | D40: 10016098561592 | F40: 700 | G40: 31 | H40: 0 | I40: =G40-H40 -> 31 | J40: =F40/G40*I40 -> 700 | L40: =F40/30/8*1.25*K40 -> 0 | N40: =F40/30/8*1.25*M40 -> 0 | P40: =F40/30/8*1.5*O40 -> 0 | Q40: =I40 -> 31 | R40: 200 | S40: =R40/G40*Q40 -> 200 | T40: =100/G40*I40 -> 100 | U40: 100 | V40: 0 | W40: 0 | X40: =J40+L40+N40+P40+S40+T40+U40+V40-W40 -> 1100 | AA40: =J40 -> 700 | AB40: =X40-AA40 -> 400 | AC40: =AE40+AB40 -> #N/A | AD40: =X40-AC40 -> #N/A | AE40: =VLOOKUP(B40,[2]Sheet1!$B$4:$J$188,9,0) -> #N/A | AF40: =X40-AE40 -> #N/A | AG40: =VLOOKUP(B40,'[3]MASTER -COLOR CODE'!$B$6:$C$337,2,0) -> DARSHAN AMRIT PAL
...

Sheet JUNE Working File  (2)
A2: Sl | B2: ID | C2: Names | D2: Cont salry | E2: Basic | F2: Other Allowances | G2: Food Allowance | H2: Salary Total | I2: days | J2: Abs. | K2: pres | L2: Basic Salary | M2: Wps OT Hours | N2: WPS OT Salary | O2: NON wps OT Hours | P2: NON wps OT Salary | Q2: Sunday OT Hours | R2: Sunday OT Amount | S2: Holiday OT | T2: Holiday OT Amount | U2: food days | V2: Food Amount | W2: Full Att entitled | X2: Full att. | Y2: Other Allowances | Z2: Add. For PH | AA2: Dedu. | AB2: Total salary | AC2: Addition Reason | AD2: Deduction Reason | AF2: Non WPS to be sent
A3: 1 | B3: 75 | C3: MD SHAHBAZ MUHAMMAD AFZAL | E3: 800 | F3: 200 | G3: 200 | H3: =E3+F3+G3 -> 1200 | I3: 30 | J3: 0 | K3: =I3-J3 -> 30 | L3: =E3/I3*K3 -> 800 | M3: 50 | N3: =E3/30/8*1.25*M3 -> 208.33333 | O3: 122.5 | P3: =E3/30*O3/8*1.25 -> 510.41667 | Q3: 28 | R3: =E3/30*Q3/8*1.5 -> 140 | S3: 12.5 | T3: =E3/30*S3/8*2.5 -> 104.16667 | U3: =K3 -> 30 | V3: =G3/I3*U3 -> 200 | W3: 100 | X3: 100 | Y3: =F3/I3*K3 -> 200 | Z3: 50 | AB3: =L3+N3+P3+R3+V3+X3+Y3+Z3-AA3+T3 -> 2312.9167 | AE3: 800 | AF3: =AB3-AE3 -> 1512.9167
A4: =A3+1 -> 2 | B4: 182 | C4: Horamoni | E4: 800 | F4: 200 | G4: 200 | H4: =E4+F4+G4 -> 1200 | I4: 30 | J4: 0 | K4: =I4-J4 -> 30 | L4: =E4/I4*K4 -> 800 | M4: 48 | N4: =E4/30/8*1.25*M4 -> 200 | O4: 39 | P4: =E4/30*O4/8*1.25 -> 162.5 | Q4: 14.5 | R4: =E4/30*Q4/8*1.5 -> 72.5 | S4: 9.5 | T4: =E4/30*S4/8*2.5 -> 79.166667 | U4: =K4 -> 30 | V4: =G4/I4*U4 -> 200 | W4: 100 | X4: 100 | Y4: =F4/I4*K4 -> 200 | Z4: 25 | AB4: =L4+N4+P4+R4+V4+X4+Y4+Z4-AA4+T4 -> 1839.1667 | AE4: 773 | AF4: =AB4-AE4 -> 1066.1667
A5: =A4+1 -> 3 | B5: 189 | C5: KAMAL ABDUR RAHMAN | E5: 800 | F5: 200 | G5: 200 | H5: =E5+F5+G5 -> 1200 | I5: 30 | J5: 0 | K5: =I5-J5 -> 30 | L5: =E5/I5*K5 -> 800 | M5: 50 | N5: =E5/30/8*1.25*M5 -> 208.33333 | O5: 13 | P5: =E5/30*O5/8*1.25 -> 54.166667 | Q5: 6.5 | R5: =E5/30*Q5/8*1.5 -> 32.5 | S5: 11 | T5: =E5/30*S5/8*2.5 -> 91.666667 | U5: =K5 -> 30 | V5: =G5/I5*U5 -> 200 | W5: 100 | X5: 100 | Y5: =F5/I5*K5 -> 200 | Z5: 0 | AB5: =L5+N5+P5+R5+V5+X5+Y5+Z5-AA5+T5 -> 1686.6667 | AE5: 800 | AF5: =AB5-AE5 -> 886.66667
A6: =A5+1 -> 4 | B6: 213 | C6: MUBARAK KALU BHUIYAN | E6: 800 | F6: 200 | G6: 200 | H6: =E6+F6+G6 -> 1200 | I6: 30 | J6: 0 | K6: =I6-J6 -> 30 | L6: =E6/I6*K6 -> 800 | M6: 50 | N6: =E6/30/8*1.25*M6 -> 208.33333 | O6: 25 | P6: =E6/30*O6/8*1.25 -> 104.16667 | Q6: 24 | R6: =E6/30*Q6/8*1.5 -> 120 | S6: 11 | T6: =E6/30*S6/8*2.5 -> 91.666667 | U6: =K6 -> 30 | V6: =G6/I6*U6 -> 200 | W6: 100 | X6: 100 | Y6: =F6/I6*K6 -> 200 | Z6: 50 | AB6: =L6+N6+P6+R6+V6+X6+Y6+Z6-AA6+T6 -> 1874.1667 | AE6: 800 | AF6: =AB6-AE6 -> 1074.1667
A7: =A6+1 -> 5 | B7: 231 | C7: MORSHAD ALAM ABUL KALAM | E7: 800 | F7: 200 | G7: 200 | H7: =E7+F7+G7 -> 1200 | I7: 30 | J7: 30 | K7: =I7-J7 -> 0 | L7: =E7/I7*K7 -> 0 | M7: 0 | N7: =E7/30/8*1.25*M7 -> 0 | O7: 0 | P7: =E7/30*O7/8*1.25 -> 0 | Q7: 0 | R7: =E7/30*Q7/8*1.5 -> 0 | S7: 0 | T7: =E7/30*S7/8*2.5 -> 0 | U7: =K7 -> 0 | V7: =G7/I7*U7 -> 0 | W7: 100 | X7: =W7/I7*K7 -> 0 | Y7: =F7/I7*K7 -> 0 | Z7: 0 | AB7: =L7+N7+P7+R7+V7+X7+Y7+Z7-AA7+T7 -> 0 | AE7: 0 | AF7: =AB7-AE7 -> 0
A8: =A7+1 -> 6 | B8: 234 | C8: AZIZAR MD ROSHAN | E8: 800 | F8: 200 | G8: 200 | H8: =E8+F8+G8 -> 1200 | I8: 30 | J8: 0 | K8: =I8-J8 -> 30 | L8: =E8/I8*K8 -> 800 | M8: 50 | N8: =E8/30/8*1.25*M8 -> 208.33333 | O8: 0 | P8: =E8/30*O8/8*1.25 -> 0 | Q8: 0 | R8: =E8/30*Q8/8*1.5 -> 0 | S8: 0 | T8: =E8/30*S8/8*2.5 -> 0 | U8: =K8 -> 30 | V8: =G8/I8*U8 -> 200 | W8: 100 | X8: 100 | Y8: =F8/I8*K8 -> 200 | Z8: 0 | AB8: =L8+N8+P8+R8+V8+X8+Y8+Z8-AA8+T8 -> 1508.3333 | AE8: 800 | AF8: =AB8-AE8 -> 708.33333
A9: =A8+1 -> 7 | B9: 245 | C9: Abu Bakkar | E9: 800 | F9: 200 | G9: 200 | H9: =E9+F9+G9 -> 1200 | I9: 30 | J9: 0 | K9: =I9-J9 -> 30 | L9: =E9/I9*K9 -> 800 | M9: 50 | N9: =E9/30/8*1.25*M9 -> 208.33333 | O9: 0 | P9: =E9/30*O9/8*1.25 -> 0 | Q9: 0 | R9: =E9/30*Q9/8*1.5 -> 0 | S9: 0 | T9: =E9/30*S9/8*2.5 -> 0 | U9: =K9 -> 30 | V9: 0 | W9: 100 | X9: =W9/I9*K9 -> 100 | Y9: =F9/I9*K9 -> 200 | Z9: 0 | AB9: =L9+N9+P9+R9+V9+X9+Y9+Z9-AA9+T9 -> 1308.3333 | AE9: 800 | AF9: =AB9-AE9 -> 508.33333
A10: =A9+1 -> 8 | B10: 247 | C10: NAZRUL ABDUL MALAK | E10: 800 | F10: 200 | G10: 200 | H10: =E10+F10+G10 -> 1200 | I10: 30 | J10: 0 | K10: =I10-J10 -> 30 | L10: =E10/I10*K10 -> 800 | M10: 50 | N10: =E10/30/8*1.25*M10 -> 208.33333 | O10: 25 | P10: =E10/30*O10/8*1.25 -> 104.16667 | Q10: 28 | R10: =E10/30*Q10/8*1.5 -> 140 | S10: 11 | T10: =E10/30*S10/8*2.5 -> 91.666667 | U10: =K10 -> 30 | V10: =G10/I10*U10 -> 200 | W10: 100 | X10: 100 | Y10: =F10/I10*K10 -> 200 | Z10: 50 | AB10: =L10+N10+P10+R10+V10+X10+Y10+Z10-AA10+T10 -> 1894.1667 | AE10: 800 | AF10: =AB10-AE10 -> 1094.1667
A11: =A10+1 -> 9 | B11: 250 | C11: JAKIR HOSSAIN SIRAJ UDDOULA | E11: 800 | F11: 200 | G11: 200 | H11: =E11+F11+G11 -> 1200 | I11: 30 | J11: 0 | K11: =I11-J11 -> 30 | L11: =E11/I11*K11 -> 800 | M11: 50 | N11: =E11/30/8*1.25*M11 -> 208.33333 | O11: 0 | P11: =E11/30*O11/8*1.25 -> 0 | Q11: 0 | R11: =E11/30*Q11/8*1.5 -> 0 | S11: 0 | T11: =E11/30*S11/8*2.5 -> 0 | U11: =K11 -> 30 | V11: =G11/I11*U11 -> 200 | W11: 100 | X11: =W11/I11*K11 -> 100 | Y11: =F11/I11*K11 -> 200 | Z11: 0 | AB11: =L11+N11+P11+R11+V11+X11+Y11+Z11-AA11+T11 -> 1508.3333 | AE11: 800 | AF11: =AB11-AE11 -> 708.33333
A12: =A11+1 -> 10 | B12: 265 | C12: Jamal Abdul Rahman | E12: 800 | F12: 200 | G12: 200 | H12: =E12+F12+G12 -> 1200 | I12: 30 | J12: 0 | K12: =I12-J12 -> 30 | L12: =E12/I12*K12 -> 800 | M12: 50 | N12: =E12/30/8*1.25*M12 -> 208.33333 | O12: 0 | P12: =E12/30*O12/8*1.25 -> 0 | Q12: 10 | R12: =E12/30*Q12/8*1.5 -> 50 | S12: 0 | T12: =E12/30*S12/8*2.5 -> 0 | U12: =K12 -> 30 | V12: 0 | W12: 100 | X12: 100 | Y12: =F12/I12*K12 -> 200 | Z12: 0 | AB12: =L12+N12+P12+R12+V12+X12+Y12+Z12-AA12+T12 -> 1358.3333 | AE12: 800 | AF12: =AB12-AE12 -> 558.33333
A13: =A12+1 -> 11 | B13: 484 | C13: MD MANSUR ALAM | E13: 800 | F13: 200 | G13: 200 | H13: =E13+F13+G13 -> 1200 | I13: 30 | J13: 12 | K13: =I13-J13 -> 18 | L13: =E13/I13*K13 -> 480 | M13: 30 | N13: =E13/30/8*1.25*M13 -> 125 | O13: 31 | P13: =E13/30*O13/8*1.25 -> 129.16667 | Q13: 10 | R13: =E13/30*Q13/8*1.5 -> 50 | S13: 6.5 | T13: =E13/30*S13/8*2.5 -> 54.166667 | U13: =K13 -> 18 | V13: =G13/I13*U13 -> 120 | W13: 100 | X13: 0 | Y13: =F13/I13*K13 -> 120 | Z13: 0 | AB13: =L13+N13+P13+R13+V13+X13+Y13+Z13-AA13+T13 -> 1078.3333 | AE13: 507 | AF13: =AB13-AE13 -> 571.33333
A14: =A13+1 -> 12 | B14: 603 | C14: TAUSEEF ALI BAGHDAD SHAH | E14: 700 | F14: 300 | G14: 200 | H14: =E14+F14+G14 -> 1200 | I14: 30 | J14: 0 | K14: =I14-J14 -> 30 | L14: =E14/I14*K14 -> 700 | M14: 50 | N14: =E14/30/8*1.25*M14 -> 182.29167 | O14: 25 | P14: =E14/30*O14/8*1.25 -> 91.145833 | Q14: 18 | R14: =E14/30*Q14/8*1.5 -> 78.75 | S14: 11 | T14: =E14/30*S14/8*2.5 -> 80.208333 | U14: =K14 -> 30 | V14: =G14/I14*U14 -> 200 | W14: 100 | X14: 100 | Y14: =F14/I14*K14 -> 300 | Z14: 50 | AB14: =L14+N14+P14+R14+V14+X14+Y14+Z14-AA14+T14 -> 1782.3958 | AE14: 700 | AF14: =AB14-AE14 -> 1082.3958
A15: =A14+1 -> 13 | B15: 604 | C15: Imdad Ali | E15: 700 | F15: 300 | G15: 200 | H15: =E15+F15+G15 -> 1200 | I15: 30 | J15: 0 | K15: =I15-J15 -> 30 | L15: =E15/I15*K15 -> 700 | M15: 50 | N15: =E15/30/8*1.25*M15 -> 182.29167 | O15: 51 | P15: =E15/30*O15/8*1.25 -> 185.9375 | Q15: 12 | R15: =E15/30*Q15/8*1.5 -> 52.5 | S15: 11 | T15: =E15/30*S15/8*2.5 -> 80.208333 | U15: =K15 -> 30 | V15: =G15/I15*U15 -> 200 | W15: 100 | X15: 100 | Y15: =F15/I15*K15 -> 300 | Z15: 25 | AB15: =L15+N15+P15+R15+V15+X15+Y15+Z15-AA15+T15 -> 1825.9375 | AE15: 700 | AF15: =AB15-AE15 -> 1125.9375
A16: =A15+1 -> 14 | B16: 606 | C16: AZEEM KHAN MUHAMMAD BASHIR | E16: 900 | F16: 200 | G16: 200 | H16: =E16+F16+G16 -> 1300 | I16: 30 | J16: 0 | K16: =I16-J16 -> 30 | L16: =E16/I16*K16 -> 900 | M16: 48 | N16: =E16/30/8*1.25*M16 -> 225 | O16: 24 | P16: =E16/30*O16/8*1.25 -> 112.5 | Q16: 12 | R16: =E16/30*Q16/8*1.5 -> 67.5 | S16: 11 | T16: =E16/30*S16/8*2.5 -> 103.125 | U16: =K16 -> 30 | V16: =G16/I16*U16 -> 200 | W16: 100 | X16: =W16/I16*K16 -> 100 | Y16: =F16/I16*K16 -> 200 | Z16: 25 | AB16: =L16+N16+P16+R16+V16+X16+Y16+Z16-AA16+T16 -> 1933.125 | AE16: 900 | AF16: =AB16-AE16 -> 1033.125
A17: =A16+1 -> 15 | B17: 626 | C17: RIYAJUDDEEN ANSARI RAHAMAN ANSARI | E17: 900 | F17: 100 | G17: 200 | H17: =E17+F17+G17 -> 1200 | I17: 30 | J17: 0 | K17: =I17-J17 -> 30 | L17: =E17/I17*K17 -> 900 | M17: 50 | N17: =E17/30/8*1.25*M17 -> 234.375 | O17: 13 | P17: =E17/30*O17/8*1.25 -> 60.9375 | Q17: 6.5 | R17: =E17/30*Q17/8*1.5 -> 36.5625 | S17: 11 | T17: =E17/30*S17/8*2.5 -> 103.125 | U17: =K17 -> 30 | V17: =G17/I17*U17 -> 200 | W17: 100 | X17: 100 | Y17: =F17/I17*K17 -> 100 | Z17: 0 | AB17: =L17+N17+P17+R17+V17+X17+Y17+Z17-AA17+T17 -> 1735 | AE17: 900 | AF17: =AB17-AE17 -> 835
A18: =A17+1 -> 16 | B18: 652 | C18: RAM VILASH SINGH YADAV | E18: 900 | F18: 100 | G18: 200 | H18: =E18+F18+G18 -> 1200 | I18: 30 | J18: 2 | K18: =I18-J18 -> 28 | L18: =E18/I18*K18 -> 840 | M18: 44 | N18: =E18/30/8*1.25*M18 -> 206.25 | O18: 22 | P18: =E18/30*O18/8*1.25 -> 103.125 | Q18: 18 | R18: =E18/30*Q18/8*1.5 -> 101.25 | S18: 11 | T18: =E18/30*S18/8*2.5 -> 103.125 | U18: =K18 -> 28 | V18: =G18/I18*U18 -> 186.66667 | W18: 100 | X18: 0 | Y18: =F18/I18*K18 -> 93.333333 | Z18: 50 | AB18: =L18+N18+P18+R18+V18+X18+Y18+Z18-AA18+T18 -> 1683.75 | AE18: 840 | AF18: =AB18-AE18 -> 843.75
A19: =A18+1 -> 17 | B19: 662 | C19: SHAILESH YADAV VEERA YADAV | E19: 900 | F19: 100 | G19: 200 | H19: =E19+F19+G19 -> 1200 | I19: 30 | J19: 0 | K19: =I19-J19 -> 30 | L19: =E19/I19*K19 -> 900 | M19: 50 | N19: =E19/30/8*1.25*M19 -> 234.375 | O19: 0 | P19: =E19/30*O19/8*1.25 -> 0 | Q19: 0 | R19: =E19/30*Q19/8*1.5 -> 0 | S19: 0 | T19: =E19/30*S19/8*2.5 -> 0 | U19: =K19 -> 30 | V19: 0 | W19: 100 | X19: 100 | Y19: =F19/I19*K19 -> 100 | Z19: 0 | AB19: =L19+N19+P19+R19+V19+X19+Y19+Z19-AA19+T19 -> 1334.375 | AE19: 900 | AF19: =AB19-AE19 -> 434.375
A20: =A19+1 -> 18 | B20: 669 | C20: MAHENDRA THAPA GAJE THAPA | E20: 700 | F20: 100 | G20: 200 | H20: =E20+F20+G20 -> 1000 | I20: 30 | J20: 21 | K20: =I20-J20 -> 9 | L20: =E20/I20*K20 -> 210 | M20: 16 | N20: =E20/30/8*1.25*M20 -> 58.333333 | O20: 16 | P20: =E20/30*O20/8*1.25 -> 58.333333 | Q20: 0 | R20: =E20/30*Q20/8*1.5 -> 0 | S20: 0 | T20: =E20/30*S20/8*2.5 -> 0 | U20: =K20 -> 9 | V20: =G20/I20*U20 -> 60 | W20: 100 | X20: 0 | Y20: =F20/I20*K20 -> 30 | Z20: 0 | AB20: =L20+N20+P20+R20+V20+X20+Y20+Z20-AA20+T20 -> 416.66667 | AE20: 210 | AF20: =AB20-AE20 -> 206.66667
A21: =A20+1 -> 19 | B21: 670 | C21: BIKRAM YADAV TILAKRAM YADAV | E21: 800 | F21: 100 | G21: 200 | H21: =E21+F21+G21 -> 1100 | I21: 30 | J21: 0 | K21: =I21-J21 -> 30 | L21: =E21/I21*K21 -> 800 | M21: 50 | N21: =E21/30/8*1.25*M21 -> 208.33333 | O21: 30 | P21: =E21/30*O21/8*1.25 -> 125 | Q21: 32 | R21: =E21/30*Q21/8*1.5 -> 160 | S21: 11 | T21: =E21/30*S21/8*2.5 -> 91.666667 | U21: =K21 -> 30 | V21: =G21/I21*U21 -> 200 | W21: 100 | X21: =W21/I21*K21 -> 100 | Y21: =F21/I21*K21 -> 100 | Z21: 50 | AB21: =L21+N21+P21+R21+V21+X21+Y21+Z21-AA21+T21 -> 1835 | AE21: 800 | AF21: =AB21-AE21 -> 1035
A22: =A21+1 -> 20 | B22: 693 | C22: AMIT KUMAR UPADHYAY | E22: 800 | F22: 100 | G22: 200 | H22: =E22+F22+G22 -> 1100 | I22: 30 | J22: 0 | K22: =I22-J22 -> 30 | L22: =E22/I22*K22 -> 800 | M22: 48 | N22: =E22/30/8*1.25*M22 -> 200 | O22: 12 | P22: =E22/30*O22/8*1.25 -> 50 | Q22: 6.5 | R22: =E22/30*Q22/8*1.5 -> 32.5 | S22: 11 | T22: =E22/30*S22/8*2.5 -> 91.666667 | U22: =K22 -> 30 | V22: =G22/I22*U22 -> 200 | W22: 100 | X22: =W22/I22*K22 -> 100 | Y22: =F22/I22*K22 -> 100 | Z22: 0 | AB22: =L22+N22+P22+R22+V22+X22+Y22+Z22-AA22+T22 -> 1574.1667 | AE22: 800 | AF22: =AB22-AE22 -> 774.16667
A23: =A22+1 -> 21 | B23: 695 | C23: TEJ BAHADUR RANA | E23: 700 | F23: 100 | G23: 200 | H23: =E23+F23+G23 -> 1000 | I23: 30 | J23: 0 | K23: =I23-J23 -> 30 | L23: =E23/I23*K23 -> 700 | M23: 48 | N23: =E23/30/8*1.25*M23 -> 175 | O23: 0 | P23: =E23/30*O23/8*1.25 -> 0 | Q23: 0 | R23: =E23/30*Q23/8*1.5 -> 0 | S23: 0 | T23: =E23/30*S23/8*2.5 -> 0 | U23: =K23 -> 30 | V23: =G23/I23*U23 -> 200 | W23: 100 | X23: =W23/I23*K23 -> 100 | Y23: =F23/I23*K23 -> 100 | Z23: 0 | AB23: =L23+N23+P23+R23+V23+X23+Y23+Z23-AA23+T23 -> 1275 | AE23: 700 | AF23: =AB23-AE23 -> 575
A24: =A23+1 -> 22 | B24: 704 | C24: RAM RATTAN CHAUHAN | E24: 900 | F24: 100 | G24: 200 | H24: =E24+F24+G24 -> 1200 | I24: 30 | J24: 1 | K24: =I24-J24 -> 29 | L24: =E24/I24*K24 -> 870 | M24: 48 | N24: =E24/30/8*1.25*M24 -> 225 | O24: 0 | P24: =E24/30*O24/8*1.25 -> 0 | Q24: 0 | R24: =E24/30*Q24/8*1.5 -> 0 | S24: 0 | T24: =E24/30*S24/8*2.5 -> 0 | U24: =K24 -> 29 | V24: 0 | W24: 100 | X24: 0 | Y24: =F24/I24*K24 -> 96.666667 | Z24: 0 | AB24: =L24+N24+P24+R24+V24+X24+Y24+Z24-AA24+T24 -> 1191.6667 | AE24: 900 | AF24: =AB24-AE24 -> 291.66667
A25: =A24+1 -> 23 | B25: 777 | C25: JAYRAM MUKHRAN | E25: 800 | F25: 200 | G25: 200 | H25: =E25+F25+G25 -> 1200 | I25: 30 | J25: 1 | K25: =I25-J25 -> 29 | L25: =E25/I25*K25 -> 773.33333 | M25: 48 | N25: =E25/30/8*1.25*M25 -> 200 | O25: 53.5 | P25: =E25/30*O25/8*1.25 -> 222.91667 | Q25: 32 | R25: =E25/30*Q25/8*1.5 -> 160 | S25: 0 | T25: =E25/30*S25/8*2.5 -> 0 | U25: =K25 -> 29 | V25: =G25/I25*U25 -> 193.33333 | W25: 100 | X25: 0 | Y25: =F25/I25*K25 -> 193.33333 | Z25: 50 | AB25: =L25+N25+P25+R25+V25+X25+Y25+Z25-AA25+T25 -> 1792.9167 | AE25: 773 | AF25: =AB25-AE25 -> 1019.9167
A26: =A25+1 -> 24 | B26: 790 | C26: RABINDRA DAS TATMA | E26: 700 | F26: 200 | G26: 200 | H26: =E26+F26+G26 -> 1100 | I26: 30 | J26: 0 | K26: =I26-J26 -> 30 | L26: =E26/I26*K26 -> 700 | M26: 50 | N26: =E26/30/8*1.25*M26 -> 182.29167 | O26: 0 | P26: =E26/30*O26/8*1.25 -> 0 | Q26: 0 | R26: =E26/30*Q26/8*1.5 -> 0 | S26: 0 | T26: =E26/30*S26/8*2.5 -> 0 | U26: =K26 -> 30 | V26: 0 | W26: 100 | X26: 100 | Y26: =F26/I26*K26 -> 200 | Z26: 0 | AB26: =L26+N26+P26+R26+V26+X26+Y26+Z26-AA26+T26 -> 1182.2917 | AE26: 700 | AF26: =AB26-AE26 -> 482.29167
A27: =A26+1 -> 25 | B27: 814 | C27: SANJAY KUMAR MANDAL | E27: 700 | F27: 200 | G27: 200 | H27: =E27+F27+G27 -> 1100 | I27: 30 | J27: 0 | K27: =I27-J27 -> 30 | L27: =E27/I27*K27 -> 700 | M27: 50 | N27: =E27/30/8*1.25*M27 -> 182.29167 | O27: 0 | P27: =E27/30*O27/8*1.25 -> 0 | Q27: 10 | R27: =E27/30*Q27/8*1.5 -> 43.75 | S27: 0 | T27: =E27/30*S27/8*2.5 -> 0 | U27: =K27 -> 30 | V27: 0 | W27: 100 | X27: 100 | Y27: =F27/I27*K27 -> 200 | Z27: 0 | AB27: =L27+N27+P27+R27+V27+X27+Y27+Z27-AA27+T27 -> 1226.0417 | AE27: 700 | AF27: =AB27-AE27 -> 526.04167
A28: =A27+1 -> 26 | B28: 818 | C28: MANOJ YADAV RAM ADHAR YADAV | E28: 900 | F28: 100 | G28: 200 | H28: =E28+F28+G28 -> 1200 | I28: 30 | J28: 0 | K28: =I28-J28 -> 30 | L28: =E28/I28*K28 -> 900 | M28: 50 | N28: =E28/30/8*1.25*M28 -> 234.375 | O28: 61.5 | P28: =E28/30*O28/8*1.25 -> 288.28125 | Q28: 32 | R28: =E28/30*Q28/8*1.5 -> 180 | S28: 0 | T28: =E28/30*S28/8*2.5 -> 0 | U28: =K28 -> 30 | V28: =G28/I28*U28 -> 200 | W28: 100 | X28: 100 | Y28: =F28/I28*K28 -> 100 | Z28: 50 | AB28: =L28+N28+P28+R28+V28+X28+Y28+Z28-AA28+T28 -> 2052.6562 | AE28: 900 | AF28: =AB28-AE28 -> 1152.6562
A29: =A28+1 -> 27 | B29: 821 | C29: Shankar singh | E29: 900 | F29: 100 | G29: 200 | H29: =E29+F29+G29 -> 1200 | I29: 30 | J29: 0 | K29: =I29-J29 -> 30 | L29: =E29/I29*K29 -> 900 | M29: 50 | N29: =E29/30/8*1.25*M29 -> 234.375 | O29: 24 | P29: =E29/30*O29/8*1.25 -> 112.5 | Q29: 15 | R29: =E29/30*Q29/8*1.5 -> 84.375 | S29: 0 | T29: =E29/30*S29/8*2.5 -> 0 | U29: =K29 -> 30 | V29: =G29/I29*U29 -> 200 | W29: 100 | X29: =W29/I29*K29 -> 100 | Y29: =F29/I29*K29 -> 100 | Z29: 225 | AB29: =L29+N29+P29+R29+V29+X29+Y29+Z29-AA29+T29 -> 1956.25 | AE29: 900 | AF29: =AB29-AE29 -> 1056.25
A30: =A29+1 -> 28 | B30: 836 | C30: Girijesh Paras Nath | E30: 800 | F30: 100 | G30: 200 | H30: =E30+F30+G30 -> 1100 | I30: 30 | J30: 0 | K30: =I30-J30 -> 30 | L30: =E30/I30*K30 -> 800 | M30: 50 | N30: =E30/30/8*1.25*M30 -> 208.33333 | O30: 25 | P30: =E30/30*O30/8*1.25 -> 104.16667 | Q30: 28 | R30: =E30/30*Q30/8*1.5 -> 140 | S30: 11 | T30: =E30/30*S30/8*2.5 -> 91.666667 | U30: =K30 -> 30 | V30: =G30/I30*U30 -> 200 | W30: 100 | X30: 100 | Y30: =F30/I30*K30 -> 100 | Z30: 50 | AA30: 200 | AB30: =L30+N30+P30+R30+V30+X30+Y30+Z30-AA30+T30 -> 1594.1667 | AD30: Extra Vacation Penalty | AE30: 800 | AF30: =AB30-AE30 -> 794.16667
A31: =A30+1 -> 29 | B31: 837 | C31: Ram lakhan | E31: 900 | F31: 100 | G31: 200 | H31: =E31+F31+G31 -> 1200 | I31: 30 | J31: 4 | K31: =I31-J31 -> 26 | L31: =E31/I31*K31 -> 780 | M31: 40 | N31: =E31/30/8*1.25*M31 -> 187.5 | O31: 27.5 | P31: =E31/30*O31/8*1.25 -> 128.90625 | Q31: 8 | R31: =E31/30*Q31/8*1.5 -> 45 | S31: 0 | T31: =E31/30*S31/8*2.5 -> 0 | U31: =K31 -> 26 | V31: =G31/I31*U31 -> 173.33333 | W31: 100 | X31: 0 | Y31: =F31/I31*K31 -> 86.666667 | Z31: 0 | AA31: 50 | AB31: =L31+N31+P31+R31+V31+X31+Y31+Z31-AA31+T31 -> 1351.4062 | AD31: Extra Absent | AE31: 780 | AF31: =AB31-AE31 -> 571.40625
A32: =A31+1 -> 30 | B32: 840 | C32: BAKSHISH JABBAR | E32: 900 | F32: 200 | G32: 200 | H32: =E32+F32+G32 -> 1300 | I32: 30 | J32: 0 | K32: =I32-J32 -> 30 | L32: =E32/I32*K32 -> 900 | M32: 50 | N32: =E32/30/8*1.25*M32 -> 234.375 | O32: 0 | P32: =E32/30*O32/8*1.25 -> 0 | Q32: 0 | R32: =E32/30*Q32/8*1.5 -> 0 | S32: 0 | T32: =E32/30*S32/8*2.5 -> 0 | U32: =K32 -> 30 | V32: 0 | W32: 100 | X32: 100 | Y32: =F32/I32*K32 -> 200 | Z32: 0 | AB32: =L32+N32+P32+R32+V32+X32+Y32+Z32-AA32+T32 -> 1434.375 | AE32: 900 | AF32: =AB32-AE32 -> 534.375
A33: =A32+1 -> 31 | B33: 845 | C33: HARIDWAR CHAUHAN | E33: 900 | F33: 100 | G33: 200 | H33: =E33+F33+G33 -> 1200 | I33: 30 | J33: 0 | K33: =I33-J33 -> 30 | L33: =E33/I33*K33 -> 900 | M33: 50 | N33: =E33/30/8*1.25*M33 -> 234.375 | O33: 70.5 | P33: =E33/30*O33/8*1.25 -> 330.46875 | Q33: 31 | R33: =E33/30*Q33/8*1.5 -> 174.375 | S33: 9.5 | T33: =E33/30*S33/8*2.5 -> 89.0625 | U33: =K33 -> 30 | V33: =G33/I33*U33 -> 200 | W33: 100 | X33: =W33/I33*K33 -> 100 | Y33: =F33/I33*K33 -> 100 | Z33: 50 | AB33: =L33+N33+P33+R33+V33+X33+Y33+Z33-AA33+T33 -> 2178.2812 | AE33: 900 | AF33: =AB33-AE33 -> 1278.2812
A34: =A33+1 -> 32 | B34: 848 | C34: DARSHAN AMRIT PAL | E34: 700 | F34: 200 | G34: 200 | H34: =E34+F34+G34 -> 1100 | I34: 30 | J34: 11 | K34: =I34-J34 -> 19 | L34: =E34/I34*K34 -> 443.33333 | M34: 32 | N34: =E34/30/8*1.25*M34 -> 116.66667 | O34: 4 | P34: =E34/30*O34/8*1.25 -> 14.583333 | Q34: 0 | R34: =E34/30*Q34/8*1.5 -> 0 | S34: 11 | T34: =E34/30*S34/8*2.5 -> 80.208333 | U34: =K34 -> 19 | V34: =G34/I34*U34 -> 126.66667 | W34: 100 | X34: 0 | Y34: =F34/I34*K34 -> 126.66667 | Z34: 0 | AB34: =L34+N34+P34+R34+V34+X34+Y34+Z34-AA34+T34 -> 908.125 | AE34: 443 | AF34: =AB34-AE34 -> 465.125
A35: =A34+1 -> 33 | B35: 849 | C35: PARDESHI GURUSANT | E35: 900 | F35: 100 | G35: 200 | H35: =E35+F35+G35 -> 1200 | I35: 30 | J35: 13 | K35: =I35-J35 -> 17 | L35: =E35/I35*K35 -> 510 | M35: 28 | N35: =E35/30/8*1.25*M35 -> 131.25 | O35: 0 | P35: =E35/30*O35/8*1.25 -> 0 | Q35: 0 | R35: =E35/30*Q35/8*1.5 -> 0 | S35: 0 | T35: =E35/30*S35/8*2.5 -> 0 | U35: =K35 -> 17 | V35: =G35/I35*U35 -> 113.33333 | W35: 100 | Y35: =F35/I35*K35 -> 56.666667 | Z35: 0 | AB35: =L35+N35+P35+R35+V35+X35+Y35+Z35-AA35+T35 -> 811.25 | AE35: 480 | AF35: =AB35-AE35 -> 331.25
A36: =A35+1 -> 34 | B36: 881 | C36: Suresh Bista | E36: 700 | F36: 200 | G36: 200 | H36: =E36+F36+G36 -> 1100 | I36: 30 | J36: 0 | K36: =I36-J36 -> 30 | L36: =E36/I36*K36 -> 700 | M36: 46 | N36: =E36/30/8*1.25*M36 -> 167.70833 | O36: 11 | P36: =E36/30*O36/8*1.25 -> 40.104167 | Q36: 6.5 | R36: =E36/30*Q36/8*1.5 -> 28.4375 | S36: 11 | T36: =E36/30*S36/8*2.5 -> 80.208333 | U36: =K36 -> 30 | V36: =G36/I36*U36 -> 200 | W36: 100 | X36: 100 | Y36: =F36/I36*K36 -> 200 | Z36: 0 | AB36: =L36+N36+P36+R36+V36+X36+Y36+Z36-AA36+T36 -> 1516.4583 | AE36: 700 | AF36: =AB36-AE36 -> 816.45833
A37: =A36+1 -> 35 | B37: 963 | C37: JANAK YADAV SHIV S | D37: 1000 | E37: 800 | F37: 100 | G37: 200 | H37: =E37+F37+G37 -> 1100 | I37: 30 | J37: 0 | K37: =I37-J37 -> 30 | L37: =E37/I37*K37 -> 800 | M37: 50 | N37: =E37/30/8*1.25*M37 -> 208.33333 | O37: 28.5 | P37: =E37/30*O37/8*1.25 -> 118.75 | Q37: 0 | R37: =E37/30*Q37/8*1.5 -> 0 | S37: 6.5 | T37: =E37/30*S37/8*2.5 -> 54.166667 | U37: =K37 -> 30 | V37: =G37/I37*U37 -> 200 | W37: 0 | X37: =W37/I37*K37 -> 0 | Y37: =F37/I37*K37 -> 100 | Z37: 0 | AB37: =L37+N37+P37+R37+V37+X37+Y37+Z37-AA37+T37 -> 1481.25 | AE37: 900 | AF37: =AB37-AE37 -> 581.25
A38: =A37+1 -> 36 | B38: 984 | C38: SHAMROZ NASRA DIN | E38: 700 | F38: 100 | G38: 200 | H38: =E38+F38+G38 -> 1000 | I38: 30 | J38: 0 | K38: =I38-J38 -> 30 | L38: =E38/I38*K38 -> 700 | M38: 50 | N38: =E38/30/8*1.25*M38 -> 182.29167 | O38: 43 | P38: =E38/30*O38/8*1.25 -> 156.77083 | Q38: 16 | R38: =E38/30*Q38/8*1.5 -> 70 | S38: 0 | T38: =E38/30*S38/8*2.5 -> 0 | U38: =K38 -> 30 | V38: =G38/I38*U38 -> 200 | W38: 0 | X38: =W38/I38*K38 -> 0 | Y38: =F38/I38*K38 -> 100 | Z38: 25 | AA38: 28 | AB38: =L38+N38+P38+R38+V38+X38+Y38+Z38-AA38+T38 -> 1406.0625 | AD38: Exra Vacation Penalty | AE38: 700 | AF38: =AB38-AE38 -> 706.0625
A39: =A38+1 -> 37 | B39: 985 | C39: IMRAN MIR KAMAN | E39: 700 | F39: 100 | G39: 200 | H39: =E39+F39+G39 -> 1000 | I39: 30 | J39: 1 | K39: =I39-J39 -> 29 | L39: =E39/I39*K39 -> 676.66667 | M39: 42 | N39: =E39/30/8*1.25*M39 -> 153.125 | O39: 30 | P39: =E39/30*O39/8*1.25 -> 109.375 | Q39: 14 | R39: =E39/30*Q39/8*1.5 -> 61.25 | S39: 0 | T39: =E39/30*S39/8*2.5 -> 0 | U39: =K39 -> 29 | V39: =G39/I39*U39 -> 193.33333 | W39: 0 | X39: =W39/I39*K39 -> 0 | Y39: =F39/I39*K39 -> 96.666667 | Z39: 25 | AA39: 20 | AB39: =L39+N39+P39+R39+V39+X39+Y39+Z39-AA39+T39 -> 1295.4167 | AD39: Advance Salary | AE39: 700 | AF39: =AB39-AE39 -> 595.41667
A40: =A39+1 -> 38 | B40: 995 | C40: MUNAWAR SAEED AHMAD | E40: 700 | F40: 100 | G40: 200 | H40: =E40+F40+G40 -> 1000 | I40: 30 | J40: 1 | K40: =I40-J40 -> 29 | L40: =E40/I40*K40 -> 676.66667 | M40: 44 | N40: =E40/30/8*1.25*M40 -> 160.41667 | O40: 0 | P40: =E40/30*O40/8*1.25 -> 0 | Q40: 0 | R40: =E40/30*Q40/8*1.5 -> 0 | S40: 0 | T40: =E40/30*S40/8*2.5 -> 0 | U40: =K40 -> 29 | V40: =G40/I40*U40 -> 193.33333 | W40: 0 | X40: =W40/I40*K40 -> 0 | Y40: =F40/I40*K40 -> 96.666667 | Z40: 0 | AB40: =L40+N40+P40+R40+V40+X40+Y40+Z40-AA40+T40 -> 1127.0833 | AE40: 653 | AF40: =AB40-AE40 -> 474.08333
A41: =A40+1 -> 39 | B41: 1005 | C41: SHELIM OHAB MOLLAH | E41: 900 | F41: 200 | G41: 200 | H41: =E41+F41+G41 -> 1300 | I41: 30 | J41: 0 | K41: =I41-J41 -> 30 | L41: =E41/I41*K41 -> 900 | M41: 50 | N41: =E41/30/8*1.25*M41 -> 234.375 | O41: 27 | P41: =E41/30*O41/8*1.25 -> 126.5625 | Q41: 33 | R41: =E41/30*Q41/8*1.5 -> 185.625 | S41: 11 | T41: =E41/30*S41/8*2.5 -> 103.125 | U41: =K41 -> 30 | V41: =G41/I41*U41 -> 200 | W41: 100 | X41: =W41/I41*K41 -> 100 | Y41: =F41/I41*K41 -> 200 | Z41: 50 | AB41: =L41+N41+P41+R41+V41+X41+Y41+Z41-AA41+T41 -> 2099.6875 | AE41: 900 | AF41: =AB41-AE41 -> 1199.6875
...

Sheet ID
B7: PAY SLIP
B9: Gulf Oasis Manpower Supply LLC
B10: JUNE- SALARY
B11: ID | C11: G212
B12: Names | C12: =VLOOKUP(C11,'JUNE Working File (2)'!B3:C125,2,0) -> Turan Miah Asid Miah
B13: Basic | C13: =VLOOKUP(C11,'JUNE Working File (2)'!B3:E126,4,0) -> 700 | G13: G155
B14: days | C14: 31
B15: Absent | C15: =VLOOKUP(C11,'JUNE Working File (2)'!B3:J126,9,0) -> 0
B16: pres | C16: =VLOOKUP(C11,'JUNE Working File (2)'!B3:K126,10,0) -> 30 | H16: provided | J16: EXACT
B17: Basic Salary | C17: =VLOOKUP(C11,'JUNE Working File (2)'!B3:L126,11,0) -> 700 | G17: Nor | H17: 54 | J17: Nor & NON WPS | K17: 77
B18: Wps OT Hours | C18: =VLOOKUP(C11,'JUNE Working File (2)'!B3:M126,12,0) -> 50 | G18: NON | H18: 38
B19: WPS OT Salary | C19: =VLOOKUP(C11,'JUNE Working File (2)'!B3:N126,13,0) -> 182.29167 | G19: SUN | H19: 18 | J19: SUN | K19: 57
B20: Non WPs OT Hours | C20: =VLOOKUP(C11,'JUNE Working File (2)'!B3:O126,14,0) -> 51
B21: Non WPS OT Salary | C21: =VLOOKUP(C11,'JUNE Working File (2)'!B3:P126,15,0) -> 185.9375
B22: Sunday OT Hours | C22: =VLOOKUP(C11,'JUNE Working File (2)'!B3:Q126,16,0) -> 24.5
B23: Sunday OT Amount | C23: =VLOOKUP(C11,'JUNE Working File (2)'!B3:R126,17,) -> 107.1875
B24: Holiday OT Hours | C24: =VLOOKUP(C11,'JUNE Working File (2)'!B3:S126,18,0) -> 9.5
B25: Holiday OT Amount | C25: =VLOOKUP(C11,'JUNE Working File (2)'!B3:T126,19,0) -> 69.270833
B26: food days | C26: =VLOOKUP(C11,'JUNE Working File (2)'!B3:U126,20,0) -> 30
B27: Food Allow | C27: =VLOOKUP(C11,'JUNE Working File (2)'!B3:G126,6,0) -> 200
B28: Food Amount | C28: =VLOOKUP(C11,'JUNE Working File (2)'!B3:V126,21,0) -> 200
B29: Full att. | C29: =VLOOKUP(C11,'JUNE Working File (2)'!B3:X126,23,0) -> 0
B30: Incen. | C30: =VLOOKUP(C11,'JUNE Working File (2)'!B3:Y126,24,0) -> 100
B31: Addition Incentive | C31: =VLOOKUP(C11,'JUNE Working File (2)'!B3:Z126,25,0) -> 50
B32: Dedu. | C32: =VLOOKUP(C11,'JUNE Working File (2)'!B3:AA126,26,0) -> 0
B33: Total salary | C33: =C17+C19+C21+C23+C25+C27+C29+C30+C31-C32 -> 1594.6875
B34: WPS basic | C34: =VLOOKUP(C11,'JUNE Working File (2)'!B3:AE126,30,0) -> 700
B35: NON WPS | C35: =VLOOKUP(C11,'JUNE Working File (2)'!B3:AF126,31,0) -> 894.6875
B36: ACTUAL SALARY - May | C36: =+C34+C35 -> 1594.6875

Sheet Mistake
E2: June Month Complaints
C3: Sl | D3: ID | G3: Exact OT | H3: We provide | I3: Due | J3: Amount
C4: 1 | D4: 704 | E4: Ram Ratan | F4: He was not absent any day. We deduct 1 day as absent + full attnd allow 100 dhs | I4: 130
C5: 2
C6: 3

Sheet Monthly Report
C1: Bauer - Ruwais | D1: JIHUA ROYAL WING CONT. | K1: Bauer A 1269 | S1: Bauer Sadiyath - A 1267 | Z1: Bauer A 1268
D3: Tashareek | G3: DARKGLOBE | K3: SMART DIMENSION | O3: BAUER KIZAD | T3: BAUER - SADIYATH | Z3: Bauer Yas Island
C4: June 2026 | D4: 1 | E4: 2 | F4: 3 | G4: 4 | H4: 5 | I4: 6 | J4: 7 | K4: 8 | L4: 9 | M4: 10 | N4: 11 | O4: 12 | P4: 13 | Q4: 14 | R4: 15 | S4: 16 | T4: 17 | U4: 18 | V4: 19 | W4: 20 | X4: 21 | Y4: 22 | Z4: 23 | AA4: 24 | AB4: 25 | AC4: 26 | AD4: 27 | AE4: 28 | AF4: 29 | AG4: 30
A5: SL | B5: ID | C5: NAME | D5: MO | E5: TU | F5: WE | G5: TH | H5: FR | I5: SA | J5: SU | K5: MO | L5: TU | M5: WE | N5: TH | O5: FR | P5: SA | Q5: SU | R5: MO | S5: TU | T5: WE | U5: TH | V5: FR | W5: SA | X5: SU | Y5: MO | Z5: TU | AA5: WE | AB5: TH | AC5: FR | AD5: SA | AE5: SU | AF5: MO | AG5: TU | AH5: Remarks
A6: =ROW()-5 -> 1 | B6: 234 | C6: AZIZAR MOHAMMAD ROSHAN | D6: P | E6: P | F6: P | G6: P | H6: P | I6: P | J6: P | K6: P | L6: P | M6: P | N6: P | O6: P | P6: P | Q6: P | R6: P | S6: P | T6: P | U6: P | V6: P | W6: P | X6: P | Y6: P | Z6: P | AA6: P | AB6: P | AC6: P | AD6: P | AE6: P | AF6: P | AG6: P | AH6: Bauer - Ruwais
A7: =ROW()-5 -> 2 | B7: 250 | C7: JAKIR HOSSAIN SIRAJ UDDOULA | D7: P | E7: P | F7: P | G7: P | H7: P | I7: P | J7: P | K7: P | L7: P | M7: P | N7: P | O7: P | P7: P | Q7: P | R7: P | S7: P | T7: P | U7: P | V7: P | W7: P | X7: P | Y7: P | Z7: P | AA7: P | AB7: P | AC7: P | AD7: P | AE7: P | AF7: P | AG7: P | AH7: Bauer - Ruwais
A8: =ROW()-5 -> 3 | B8: 849 | C8: PARDESHI GURUSANT | D8: P | E8: P | F8: P | G8: P | H8: P | I8: P | J8: P | K8: P | L8: P | M8: P | N8: P | O8: P | P8: P | Q8: P | R8: P | S8: P | T8: A | U8: A | V8: A | W8: A | X8: A | Y8: A | Z8: A | AA8: A | AB8: A | AC8: A | AD8: A | AE8: A | AF8: A | AG8: A | AH8: Bauer - Ruwais & Under Cancel
A9: =ROW()-5 -> 4 | B9: G72 | C9: SAMBHU CHAMAR SEEMA CHAMAR | D9: P | E9: P | F9: P | G9: P | H9: P | I9: P | J9: P | K9: P | L9: P | M9: P | N9: P | O9: P | P9: P | Q9: P | R9: P | S9: P | T9: P | U9: P | V9: P | W9: P | X9: P | Y9: P | Z9: P | AA9: P | AB9: P | AC9: P | AD9: P | AE9: P | AF9: P | AG9: P | AH9: Bauer - Ruwais
A10: =ROW()-5 -> 5 | B10: 189 | C10: KAMAL ABDUR RAHMAN | D10: P | E10: P | F10: P | G10: P | H10: P | I10: P | J10: P | K10: P | L10: P | M10: P | N10: P | O10: P | P10: P | Q10: P | R10: P | S10: P | T10: P | U10: P | V10: P | W10: P | X10: P | Y10: P | Z10: P | AA10: P | AB10: P | AC10: P | AD10: P | AE10: P | AF10: P | AG10: P | AH10: Bauer Yas Island
A11: =ROW()-5 -> 6 | B11: 626 | C11: RIYAJUDDEEN ANSARI RAHAMAN | D11: P | E11: P | F11: P | G11: P | H11: P | I11: P | J11: P | K11: P | L11: P | M11: P | N11: i | O11: P | P11: P | Q11: P | R11: P | S11: P | T11: P | U11: P | V11: P | W11: P | X11: P | Y11: P | Z11: P | AA11: P | AB11: P | AC11: P | AD11: P | AE11: P | AF11: P | AG11: P | AH11: Bauer Yas Island
A12: =ROW()-5 -> 7 | B12: 693 | C12: AMIT KUMAR UPADHYAY | D12: P | E12: P | F12: P | G12: P | H12: P | I12: P | J12: P | K12: P | L12: P | M12: P | N12: P | O12: P | P12: P | Q12: P | R12: P | S12: P | T12: P | U12: P | V12: P | W12: i | X12: P | Y12: P | Z12: P | AA12: P | AB12: P | AC12: P | AD12: P | AE12: P | AF12: P | AG12: P | AH12: Bauer Yas Island
A13: =ROW()-5 -> 8 | B13: 848 | C13: DARSHAN AMRIT LAL | D13: P | E13: P | F13: P | G13: P | H13: P | I13: P | J13: P | K13: P | L13: P | M13: P | N13: P | O13: P | P13: P | Q13: P | R13: P | S13: P | T13: P | U13: P | V13: P | W13: A | X13: A | Y13: A | Z13: V | AA13: V | AB13: V | AC13: V | AD13: V | AE13: V | AF13: V | AG13: V | AH13: Bauer Yas Island
A14: =ROW()-5 -> 9 | B14: 881 | C14: SURESH BISTA BHAGAWATI BISTA | D14: P | E14: P | F14: P | G14: P | H14: P | I14: P | J14: P | K14: P | L14: P | M14: P | N14: P | O14: P | P14: P | Q14: P | R14: P | S14: SL | T14: SL | U14: P | V14: P | W14: P | X14: P | Y14: P | Z14: P | AA14: P | AB14: P | AC14: P | AD14: P | AE14: P | AF14: P | AG14: P | AH14: Bauer Yas Island
A15: =ROW()-5 -> 10 | B15: C071 | C15: SEIKH YEASIN RAHAMAN | D15: P | E15: P | F15: P | G15: P | H15: P | I15: P | J15: P | K15: P | L15: P | M15: P | N15: P | O15: P | P15: P | Q15: P | R15: P | S15: P | T15: P | U15: P | V15: P | W15: P | X15: P | Y15: P | Z15: P | AA15: P | AB15: P | AC15: P | AD15: P | AE15: P | AF15: P | AG15: P | AH15: Bauer Yas Island
A16: =ROW()-5 -> 11 | B16: G209 | C16: MD AMAN ULLAH MD SIRAJ UDDIN | D16: P | E16: P | F16: P | G16: P | H16: P | I16: P | J16: P | K16: P | L16: P | M16: P | N16: P | O16: P | P16: P | Q16: P | R16: P | S16: P | T16: P | U16: P | V16: P | W16: P | X16: P | Y16: P | Z16: P | AA16: P | AB16: P | AC16: P | AD16: P | AE16: P | AF16: P | AG16: P | AH16: Bauer Yas Island
A17: =ROW()-5 -> 12 | B17: G210 | C17: MD SUMSUL ALOM MD SUKUR ALI | D17: P | E17: P | F17: P | G17: P | H17: P | I17: P | J17: P | K17: P | L17: P | M17: P | N17: P | O17: P | P17: P | Q17: P | R17: P | S17: P | T17: P | U17: P | V17: P | W17: P | X17: P | Y17: P | Z17: P | AA17: P | AB17: P | AC17: P | AD17: P | AE17: P | AF17: P | AG17: P | AH17: Bauer Yas Island
A18: =ROW()-5 -> 13 | B18: 1012 | C18: JAFAR UDDIN KADAM ALI | D18: P | E18: P | F18: P | G18: P | H18: P | I18: P | J18: P | K18: P | L18: P | M18: P | N18: P | O18: P | P18: P | Q18: P | R18: P | S18: P | T18: P | U18: i | V18: i | W18: i | X18: i | Y18: P | Z18: P | AA18: P | AB18: P | AC18: P | AD18: P | AE18: P | AF18: P | AG18: P | AH18: Tashareek - Dxb & Bauer Yas Island
A19: =ROW()-5 -> 14 | B19: 213 | C19: MUBARAK KALU BHUIYAN | D19: P | E19: P | F19: P | G19: P | H19: P | I19: P | J19: P | K19: P | L19: P | M19: P | N19: P | O19: P | P19: P | Q19: P | R19: P | S19: P | T19: P | U19: P | V19: P | W19: P | X19: P | Y19: P | Z19: P | AA19: P | AB19: P | AC19: P | AD19: P | AE19: P | AF19: P | AG19: P | AH19: Bauer - Kizad
A20: =ROW()-5 -> 15 | B20: 247 | C20: NAZRUL ABDUL MALIK | D20: P | E20: P | F20: P | G20: P | H20: P | I20: P | J20: P | K20: P | L20: P | M20: P | N20: P | O20: P | P20: P | Q20: P | R20: P | S20: P | T20: P | U20: P | V20: P | W20: P | X20: P | Y20: P | Z20: P | AA20: P | AB20: P | AC20: P | AD20: P | AE20: P | AF20: P | AG20: P | AH20: Bauer - Kizad
A21: =ROW()-5 -> 16 | B21: 603 | C21: TAUSEEF ALI BAGHDAD SHAH | D21: P | E21: P | F21: P | G21: P | H21: P | I21: P | J21: P | K21: P | L21: P | M21: P | N21: P | O21: P | P21: P | Q21: P | R21: P | S21: P | T21: P | U21: P | V21: P | W21: P | X21: P | Y21: P | Z21: P | AA21: P | AB21: P | AC21: P | AD21: P | AE21: P | AF21: P | AG21: P | AH21: Bauer - Kizad
A22: =ROW()-5 -> 17 | B22: 604 | C22: AMDAD ALI BHUTTO MUHAMMAD | D22: P | E22: P | F22: P | G22: P | H22: P | I22: P | J22: P | K22: P | L22: P | M22: P | N22: P | O22: P | P22: P | Q22: P | R22: P | S22: P | T22: P | U22: P | V22: P | W22: P | X22: P | Y22: P | Z22: P | AA22: P | AB22: P | AC22: P | AD22: P | AE22: P | AF22: P | AG22: P | AH22: Bauer - Kizad
A23: =ROW()-5 -> 18 | B23: 606 | C23: AZEEM KHAN MUHAMMAD BASHIR | D23: P | E23: P | F23: P | G23: P | H23: P | I23: P | J23: P | K23: P | L23: P | M23: P | N23: P | O23: P | P23: P | Q23: P | R23: P | S23: P | T23: P | U23: P | V23: P | W23: P | X23: P | Y23: SL | Z23: P | AA23: P | AB23: P | AC23: P | AD23: P | AE23: P | AF23: P | AG23: P | AH23: Bauer - Kizad
A24: =ROW()-5 -> 19 | B24: 652 | C24: RAM VILASH SINGH YADAV | D24: P | E24: P | F24: P | G24: P | H24: P | I24: P | J24: P | K24: P | L24: A | M24: P | N24: i | O24: P | P24: P | Q24: P | R24: P | S24: P | T24: P | U24: P | V24: P | W24: P | X24: P | Y24: P | Z24: A | AA24: P | AB24: P | AC24: P | AD24: P | AE24: P | AF24: P | AG24: P | AH24: Bauer Kizad
A25: =ROW()-5 -> 20 | B25: 670 | C25: BIKRAM YADAV TILAKRAM YADAV | D25: P | E25: P | F25: P | G25: P | H25: P | I25: P | J25: P | K25: P | L25: P | M25: P | N25: P | O25: P | P25: P | Q25: P | R25: P | S25: P | T25: P | U25: P | V25: P | W25: P | X25: P | Y25: P | Z25: P | AA25: P | AB25: P | AC25: P | AD25: P | AE25: P | AF25: P | AG25: P | AH25: Bauer - Kizad
A26: =ROW()-5 -> 21 | B26: 836 | C26: GIRIJESH PARAS NATH GAUTAM | D26: P | E26: P | F26: P | G26: P | H26: P | I26: P | J26: P | K26: P | L26: P | M26: P | N26: P | O26: P | P26: P | Q26: P | R26: P | S26: P | T26: P | U26: P | V26: P | W26: P | X26: P | Y26: P | Z26: P | AA26: P | AB26: P | AC26: P | AD26: P | AE26: P | AF26: P | AG26: P | AH26: Bauer - Kizad
A27: =ROW()-5 -> 22 | B27: 985 | C27: IMRAN MIR KAMAN | D27: P | E27: P | F27: P | G27: P | H27: P | I27: P | J27: P | K27: P | L27: P | M27: P | N27: P | O27: P | P27: P | Q27: P | R27: P | S27: P | T27: SL | U27: SL | V27: P | W27: A | X27: P | Y27: P | Z27: P | AA27: P | AB27: SL | AC27: P | AD27: P | AE27: P | AF27: P | AG27: P | AH27: Bauer - Kizad
